Workbook

Sheet 📊 Dashboard
A2: HYLAND — Cuentas Médicas para Prestadores de Servicios
A3: Tracker de Epics · Implementación de Funcionalidades | 2025
B5: 43 | C5: =COUNTA('E1 · Captura'!E7:E60)+COUNTA('E2 · Validación IA'!E7:E62)+COUNTA('E3 · Envío'!E7:E49)+COUNTA('E4 · Glosas'!E7:E61)+COUNTA('E5 · Apelación'!E7:E47)+COUNTA('E6 · Pago y Cierre'!E7:E55) -> 255 | E5: =COUNTIF('E1 · Captura'!F7:F60,"Completado")+COUNTIF('E2 · Validación IA'!F7:F62,"Completado")+COUNTIF('E3 · Envío'!F7:F49,"Completado")+COUNTIF('E4 · Glosas'!F7:F61,"Completado")+COUNTIF('E5 · Apelación'!F7:F47,"Completado")+COUNTIF('E6 · Pago y Cierre'!F7:F55,"Completado") -> 31 | F5: =COUNTIF('E1 · Captura'!F7:F60,"En Progreso")+COUNTIF('E2 · Validación IA'!F7:F62,"En Progreso")+COUNTIF('E3 · Envío'!F7:F49,"En Progreso")+COUNTIF('E4 · Glosas'!F7:F61,"En Progreso")+COUNTIF('E5 · Apelación'!F7:F47,"En Progreso")+COUNTIF('E6 · Pago y Cierre'!F7:F55,"En Progreso") -> 7 | G5: =COUNTIF('E1 · Captura'!F7:F60,"Bloqueado")+COUNTIF('E2 · Validación IA'!F7:F62,"Bloqueado")+COUNTIF('E3 · Envío'!F7:F49,"Bloqueado")+COUNTIF('E4 · Glosas'!F7:F61,"Bloqueado")+COUNTIF('E5 · Apelación'!F7:F47,"Bloqueado")+COUNTIF('E6 · Pago y Cierre'!F7:F55,"Bloqueado") -> 0 | H5: =COUNTIF('E1 · Captura'!F7:F60,"Pendiente")+COUNTIF('E2 · Validación IA'!F7:F62,"Pendiente")+COUNTIF('E3 · Envío'!F7:F49,"Pendiente")+COUNTIF('E4 · Glosas'!F7:F61,"Pendiente")+COUNTIF('E5 · Apelación'!F7:F47,"Pendiente")+COUNTIF('E6 · Pago y Cierre'!F7:F55,"Pendiente") -> 121
B6: Total Epics | C6: Subtareas | E6: Completadas | F6: En Progreso | G6: Bloqueadas | H6: Pendientes
B8: Etapa | C8: Epics | D8: Subtareas | E8: Completadas | F8: En Progreso | G8: Bloqueadas | H8: % Avance
B9: Etapa 1 — Captura y Estructuración del Evento Clínico | C9: 8 | D9: =COUNTA('E1 · Captura'!E7:E60) -> 46 | E9: =COUNTIF('E1 · Captura'!F7:F60,"Completado") -> 12 | F9: =COUNTIF('E1 · Captura'!F7:F60,"En Progreso") -> 6 | G9: =COUNTIF('E1 · Captura'!F7:F60,"Bloqueado") -> 0 | H9: =IFERROR(COUNTIF('E1 · Captura'!F7:F60,"Completado")/COUNTA('E1 · Captura'!E7:E60),0) -> 0.26086957
B10: Etapa 2 — Validación Previa con Agente IA | C10: 8 | D10: =COUNTA('E2 · Validación IA'!E7:E62) -> 48 | E10: =COUNTIF('E2 · Validación IA'!F7:F62,"Completado") -> 19 | F10: =COUNTIF('E2 · Validación IA'!F7:F62,"En Progreso") -> 1 | G10: =COUNTIF('E2 · Validación IA'!F7:F62,"Bloqueado") -> 0 | H10: =IFERROR(COUNTIF('E2 · Validación IA'!F7:F62,"Completado")/COUNTA('E2 · Validación IA'!E7:E62),0) -> 0.39583333
B11: Etapa 3 — Armado y Envío de la Cuenta | C11: 6 | D11: =COUNTA('E3 · Envío'!E7:E49) -> 37 | E11: =COUNTIF('E3 · Envío'!F7:F49,"Completado") -> 0 | F11: =COUNTIF('E3 · Envío'!F7:F49,"En Progreso") -> 0 | G11: =COUNTIF('E3 · Envío'!F7:F49,"Bloqueado") -> 0 | H11: =IFERROR(COUNTIF('E3 · Envío'!F7:F49,"Completado")/COUNTA('E3 · Envío'!E7:E49),0) -> 0
B12: Etapa 4 — Recepción y Gestión de Glosas | C12: 8 | D12: =COUNTA('E4 · Glosas'!E7:E61) -> 47 | E12: =COUNTIF('E4 · Glosas'!F7:F61,"Completado") -> 0 | F12: =COUNTIF('E4 · Glosas'!F7:F61,"En Progreso") -> 0 | G12: =COUNTIF('E4 · Glosas'!F7:F61,"Bloqueado") -> 0 | H12: =IFERROR(COUNTIF('E4 · Glosas'!F7:F61,"Completado")/COUNTA('E4 · Glosas'!E7:E61),0) -> 0
B13: Etapa 5 — Respuesta y Apelación de Glosas | C13: 6 | D13: =COUNTA('E5 · Apelación'!E7:E47) -> 35 | E13: =COUNTIF('E5 · Apelación'!F7:F47,"Completado") -> 0 | F13: =COUNTIF('E5 · Apelación'!F7:F47,"En Progreso") -> 0 | G13: =COUNTIF('E5 · Apelación'!F7:F47,"Bloqueado") -> 0 | H13: =IFERROR(COUNTIF('E5 · Apelación'!F7:F47,"Completado")/COUNTA('E5 · Apelación'!E7:E47),0) -> 0
B14: Etapa 6 — Seguimiento de Pago, Conciliación y Cierre | C14: 7 | D14: =COUNTA('E6 · Pago y Cierre'!E7:E55) -> 42 | E14: =COUNTIF('E6 · Pago y Cierre'!F7:F55,"Completado") -> 0 | F14: =COUNTIF('E6 · Pago y Cierre'!F7:F55,"En Progreso") -> 0 | G14: =COUNTIF('E6 · Pago y Cierre'!F7:F55,"Bloqueado") -> 0 | H14: =IFERROR(COUNTIF('E6 · Pago y Cierre'!F7:F55,"Completado")/COUNTA('E6 · Pago y Cierre'!E7:E55),0) -> 0
A15: TOTAL GENERAL | C15: 43 | D15: =COUNTA('E1 · Captura'!E7:E60)+COUNTA('E2 · Validación IA'!E7:E62)+COUNTA('E3 · Envío'!E7:E49)+COUNTA('E4 · Glosas'!E7:E61)+COUNTA('E5 · Apelación'!E7:E47)+COUNTA('E6 · Pago y Cierre'!E7:E55) -> 255 | E15: =COUNTIF('E1 · Captura'!F7:F60,"Completado")+COUNTIF('E2 · Validación IA'!F7:F62,"Completado")+COUNTIF('E3 · Envío'!F7:F49,"Completado")+COUNTIF('E4 · Glosas'!F7:F61,"Completado")+COUNTIF('E5 · Apelación'!F7:F47,"Completado")+COUNTIF('E6 · Pago y Cierre'!F7:F55,"Completado") -> 31 | F15: =COUNTIF('E1 · Captura'!F7:F60,"En Progreso")+COUNTIF('E2 · Validación IA'!F7:F62,"En Progreso")+COUNTIF('E3 · Envío'!F7:F49,"En Progreso")+COUNTIF('E4 · Glosas'!F7:F61,"En Progreso")+COUNTIF('E5 · Apelación'!F7:F47,"En Progreso")+COUNTIF('E6 · Pago y Cierre'!F7:F55,"En Progreso") -> 7 | G15: =COUNTIF('E1 · Captura'!F7:F60,"Bloqueado")+COUNTIF('E2 · Validación IA'!F7:F62,"Bloqueado")+COUNTIF('E3 · Envío'!F7:F49,"Bloqueado")+COUNTIF('E4 · Glosas'!F7:F61,"Bloqueado")+COUNTIF('E5 · Apelación'!F7:F47,"Bloqueado")+COUNTIF('E6 · Pago y Cierre'!F7:F55,"Bloqueado") -> 0 | H15: =AVERAGE(H9:H13) -> 0.13134058

Sheet E1 · Captura
A2: HYLAND | Cuentas Médicas — Prestadores de Servicios
A3: Etapa 1 — Captura y Estructuración del Evento Clínico
A4: El proceso inicia con la atención al paciente. El prestador genera documentos heterogéneos: historia clínica, órdenes médicas, resultados de laboratorio, imágenes diagnósticas y registros de enfermería. Esta etapa consolida toda esa información en un expediente digital estructurado.
B6: ☑ | C6: ✓ | D6: Epic ID | E6: Nombre del Epic | F6: Descripción | G6: Módulo Hyland | H6: Prioridad | I6: Status | J6: Responsable | K6: Fecha Inicio | L6: Fecha Límite | M6: Subtareas | N6: Completadas | O6: % Avance | P6: Comentarios / Bloqueantes
C7: =FALSE() -> FALSE | D7: E1-001 | E7: Captura multicanal de documentos | F7: Ingesta automática desde escaner, email, portal web, sistemas HIS y fax digital | G7: IDP | H7: CRÍTICA | I7: En Progreso | M7: =COUNTA(E9:E58) -> 43 | N7: =COUNTIF(F9:F58,"Completado") -> 12 | O7: =IFERROR(COUNTIF(F9:F15,"Completado")/COUNTA(E9:E15),0) -> 0.57142857 | P7: Configurar la integraciones
B8: ☑ | C8: ✓ | D8: ↳ Epic | E8: Subtarea | F8: Status | G8: Responsable | H8: Fecha Límite | I8: Comentarios
B9: 2 | C9: =FALSE() -> FALSE | D9: E1-001 | E9: Configurar conector de email (IMAP/SMTP) | F9: En Progreso | G9: Mauricio | I9: Configurar la integración con Outlook
B10: 1 | C10: =FALSE() -> FALSE | D10: E1-001 | E10: Configurar conector de escaner de red | F10: Completado | G10: Larissa | I10: Web Scanning pendiente, O incluir video en demo.
B11: 2 | C11: =FALSE() -> FALSE | D11: E1-001 | E11: Configurar upload Automate | F11: Completado | G11: Fernando | I11: Interfaz de Custom UI.
B12: 0 | C12: =FALSE() -> FALSE | D12: E1-001 | E12: Configurar integración HIS (HL7/FHIR) | F12: Completado | G12: N/A | I12: Fase 2
B13: 2 | C13: =FALSE() -> FALSE | D13: E1-001 | E13: Pruebas de ingesta multicanal (Whatsapp) | F13: En Progreso | G13: Mauricio | I13: Whatsapp
B14: 0 | D14: E1-001 | E14: Pruebas de ingesta multicanal (Sharepoint ) | F14: En Progreso | G14: Mauricio | I14: Sharepoint if possible - Fase 2
B15: 2 | D15: E1-001 | E15: Integracción de los CUPS | F15: Completado | G15: Mauricio | I15: Fase 1 - Importar JSON para simular una integracción via API Fase 2 - Integración via trigger donde el proceso empeza desde postman
C17: =FALSE() -> FALSE | D17: E1-002 | E17: Clasificación automática de documentos | F17: Identifica el tipo de documento sin configuración manual | G17: IDP | H17: CRÍTICA | I17: En Progreso | M17: =COUNTA(E19:E65) -> 35 | N17: =COUNTIF(F19:F65,"Completado") -> 8 | O17: =IFERROR(COUNTIF(F19:F23,"Completado")/COUNTA(E19:E23),0) -> 0.4 | P17: Ya se implemento una primera version de IDP basada en POC de ARS primera Faltaria definir Documentos finales para la demostración.
B18: ☑ | C18: ✓ | D18: ↳ Epic | E18: Subtarea | F18: Status | G18: Responsable | H18: Fecha Límite | I18: Comentarios
B19: 2 | C19: =FALSE() -> FALSE | D19: E1-002 | E19: Definir taxonomía de tipos de documento para la demo | F19: En Progreso | G19: Larissa | I19: Tener muestrasd documentales para la demostración, ya hay muestras de ARS primera pero hay que terminar de acotar y recolectar muestras.
B20: 2 | C20: =FALSE() -> FALSE | D20: E1-002 | E20: Entrenar modelo de clasificación IDP | F20: En Progreso | G20: Larissa
B21: 2 | D21: E1-002 | E21: Sub Clasificaciónde clases heredadas | F21: En Progreso | G21: Larissa
B22: 2 | C22: =FALSE() -> FALSE | D22: E1-002 | E22: Validar precisión (umbral ≥ 90%) Prueba de ejecución con lote de demo | F22: Completado | G22: Larissa
B23: 2 | C23: =FALSE() -> FALSE | D23: E1-002 | E23: Configurar reglas de excepción | F23: Completado | G23: Fernando
C25: =FALSE() -> FALSE | D25: E1-003 | E25: Extracción de campos clave | F25: Extrae diagnósticos CIE-10, procedimientos CUPS, medicamentos, fechas y valores | G25: IDP | H25: CRÍTICA | I25: En Progreso | M25: =COUNTA(E27:E73) -> 28 | N25: =COUNTIF(F27:F73,"Completado") -> 6 | O25: =IFERROR(COUNTIF(F27:F28,"Completado")/COUNTA(E27:E28),0) -> 1 | P25: Ya se implemento una primera version de IDP basada en POC de ARS primera Faltaria definir Documentos finales para la demostración.
B26: ☑ | C26: ✓ | D26: ↳ Epic | E26: Subtarea | F26: Status | G26: Responsable | H26: Fecha Límite | I26: Comentarios
B27: 2 | C27: =FALSE() -> FALSE | D27: E1-003 | E27: Mapear campos requeridos por aseguradora | F27: Completado | G27: Fernando
B28: 2 | C28: =FALSE() -> FALSE | D28: E1-003 | E28: Configurar extracción de valores y fechas | F28: Completado | G28: Fernando
C30: =FALSE() -> FALSE | D30: E1-004 | E30: Enriquecimiento de imágenes médicas | F30: Indexa RX, ecografías y fotografías con metadatos clínicos | G30: Knowledge Enrichment | H30: CRÍTICA | I30: =IF(C30,"Completado","Pendiente") -> Pendiente | M30: =COUNTA(E32:E80) -> 24 | N30: =COUNTIF(F32:F80,"Completado") -> 4 | O30: =IFERROR(COUNTIF(F32:F35,"Completado")/COUNTA(E32:E35),0) -> 0.25
B31: ☑ | C31: ✓ | D31: ↳ Epic | E31: Subtarea | F31: Status | G31: Responsable | H31: Fecha Límite | I31: Comentarios
B32: 2 | C32: =FALSE() -> FALSE | D32: E1-004 | E32: Configurar pipeline de Knowledge Enrichment | F32: =IF(C32,"Completado","Pendiente") -> Pendiente | G32: Mau /Lari
B33: 2 | C33: =FALSE() -> FALSE | D33: E1-004 | E33: Definir metadatos clínicos a indexar | F33: Completado | G33: Fernando
B34: 0 | C34: =FALSE() -> FALSE | D34: E1-004 | E34: Integrar con Nilread si aplica | F34: =IF(C34,"Completado","Pendiente") -> Pendiente | G34: N/A | I34: Fase 2: Agregar interfaz de Nilread
B35: 1 | C35: =FALSE() -> FALSE | D35: E1-004 | E35: Validar búsqueda semántica de imágenes | F35: =IF(C35,"Completado","Pendiente") -> Pendiente | G35: a definir | I35: Crear agente de KD para búsqueda de imagenes.
C37: =FALSE() -> FALSE | D37: E1-005 | E37: Creación del expediente unificado | F37: Consolida todos los documentos del evento en un expediente único en el ECM | G37: ECM / CIC | H37: CRÍTICA | I37: En Progreso | M37: =COUNTA(E39:E88) -> 18 | N37: =COUNTIF(F39:F88,"Completado") -> 3 | O37: =IFERROR(COUNTIF(F39:F43,"Completado")/COUNTA(E39:E43),0) -> 0 | P37: Se Inicio con la construcción de la UI de Cuenta medica, falta estructura de carpetas interna de Automate por paciente
B38: ☑ | C38: ✓ | D38: ↳ Epic | E38: Subtarea | F38: Status | G38: Responsable | H38: Fecha Límite | I38: Comentarios
C39: =FALSE() -> FALSE | D39: E1-005 | E39: Diseñar modelo de objeto del expediente en CIC | F39: =IF(C39,"Completado","Pendiente") -> Pendiente
C40: =FALSE() -> FALSE | D40: E1-005 | E40: Configurar vinculación automática por ID de paciente | F40: =IF(C40,"Completado","Pendiente") -> Pendiente
C41: =FALSE() -> FALSE | D41: E1-005 | E41: Definir reglas de agrupación de documentos Crear Content Types y Schemas | F41: =IF(C41,"Completado","Pendiente") -> Pendiente
C42: =FALSE() -> FALSE | D42: E1-005 | E42: Pruebas de creación de expediente end-to-end | F42: =IF(C42,"Completado","Pendiente") -> Pendiente
C43: =FALSE() -> FALSE | D43: E1-005 | E43: Validación de acceso por roles | F43: =IF(C43,"Completado","Pendiente") -> Pendiente
C45: =FALSE() -> FALSE | D45: E1-006 | E45: Validación de completitud documental | F45: Verifica que el expediente tenga todos los documentos requeridos antes de avanzar | G45: Agent / Automate | H45: MEDIA | I45: En Progreso | M45: =COUNTA(E47:E95) -> 11 | N45: =COUNTIF(F47:F95,"Completado") -> 3 | O45: =IFERROR(COUNTIF(F47:F50,"Completado")/COUNTA(E47:E50),0) -> 0.75 | P45: En una primera version la UI de Cuenta medica, esta haciendo las veces de Checklist Documental, esta es una tarea de uuario y se presenta en el form de Cuenta Medica, ligado al Widget instake-account.
B46: ☑ | C46: ✓ | D46: ↳ Epic | E46: Subtarea | F46: Status | G46: Responsable | H46: Fecha Límite | I46: Comentarios
C47: =FALSE() -> FALSE | D47: E1-006 | E47: Definir checklist de documentos requeridos por tipo de evento | F47: Completado | G47: Fernando
...

Sheet E2 · Validación IA
A2: HYLAND | Cuentas Médicas — Prestadores de Servicios
A3: Etapa 2 — Validación Previa con Agente IA
A4: Antes de armar y enviar la cuenta a la aseguradora, un Agente IA analiza el expediente completo en busca de inconsistencias internas: procedimientos sin diagnóstico de respaldo, códigos incorrectos, documentos faltantes o montos fuera del rango tarifario del convenio.
B6: ☑ | C6: ✓ | D6: Epic ID | E6: Nombre del Epic | F6: Descripción | G6: Módulo Hyland | H6: Prioridad | I6: Status | J6: Responsable | K6: Fecha Inicio | L6: Fecha Límite | M6: Subtareas | N6: Completadas | O6: % Avance | P6: Comentarios / Bloqueantes
C7: =FALSE() -> FALSE | D7: E2-001 | E7: Análisis de consistencia clínico-administrativa | F7: El agente verifica que cada procedimiento facturado tenga diagnóstico de respaldo válido | G7: Agente IA | H7: CRÍTICA | I7: En Progreso | M7: =COUNTA(E9:E62) -> 46 | N7: =COUNTIF(F9:F62,"Completado") -> 19 | O7: =IFERROR(COUNTIF(F9:F13,"Completado")/COUNTA(E9:E13),0) -> 0.8 | P7: Avanzo la configuración de automate y agent builder creando 3 agentes paralelos, están funcionando parcialmente por errores de agent builder.
B8: ☑ | C8: ✓ | D8: ↳ Epic | E8: Subtarea | F8: Status | G8: Responsable | H8: Fecha Límite | I8: Comentarios
C9: =FALSE() -> FALSE | D9: E2-001 | E9: Mapear reglas de consistencia por aseguradora | F9: Completado | G9: Fernando
C10: =FALSE() -> FALSE | D10: E2-001 | E10: Configurar Agent Builder con reglas de negocio | F10: Completado | G10: Fernando
C11: =FALSE() -> FALSE | D11: E2-001 | E11: Definir umbral de riesgo de glosa (%) | F11: Completado | G11: Fernando
C12: =FALSE() -> FALSE | D12: E2-001 | E12: Pruebas con casos históricos del cliente | F12: Completado | G12: Fernando
C13: =FALSE() -> FALSE | D13: E2-001 | E13: Validación con equipo auditor | F13: En Revisión
C15: =FALSE() -> FALSE | D15: E2-002 | E15: Detección de códigos CUPS incorrectos | F15: Identifica códigos de procedimiento que no corresponden al diagnóstico | G15: Agente IA + IDP | H15: CRÍTICA | I15: En Progreso | M15: =COUNTA(E17:E69) -> 39 | N15: =COUNTIF(F17:F69,"Completado") -> 15 | O15: =IFERROR(COUNTIF(F17:F20,"Completado")/COUNTA(E17:E20),0) -> 0.75 | P15: Avanzo la configuración de automate y agent builder creando 3 agentes paralelos, están funcionando parcialmente por errores de agent builder.
B16: ☑ | C16: ✓ | D16: ↳ Epic | E16: Subtarea | F16: Status | G16: Responsable | H16: Fecha Límite | I16: Comentarios
C17: =FALSE() -> FALSE | D17: E2-002 | E17: Cargar tabla vigente de códigos CUPS | F17: =IF(C17,"Completado","Pendiente") -> Pendiente
C18: =FALSE() -> FALSE | D18: E2-002 | E18: Configurar validación de correspondencia CIE-10/CUPS | F18: Completado | G18: Fernando | J18: Esto lo hace el agente directamente en una simulación
C19: =FALSE() -> FALSE | D19: E2-002 | E19: Definir acción para códigos no encontrados | F19: Completado | G19: Fernando
C20: =FALSE() -> FALSE | D20: E2-002 | E20: Pruebas de detección con errores conocidos | F20: Completado | G20: Fernando
G21: Fernando
C22: =FALSE() -> FALSE | D22: E2-003 | E22: Verificación de autorizaciones previas | F22: Cruza los procedimientos realizados contra las autorizaciones previas registradas | G22: Agente IA + ECM | H22: CRÍTICA | I22: En Progreso | M22: =COUNTA(E24:E76) -> 33 | N22: =COUNTIF(F24:F76,"Completado") -> 12 | O22: =IFERROR(COUNTIF(F24:F27,"Completado")/COUNTA(E24:E27),0) -> 0.75 | P22: Avanzo la configuración de automate y agent builder creando 3 agentes paralelos, están funcionando parcialmente por errores de agent builder.
B23: ☑ | C23: ✓ | D23: ↳ Epic | E23: Subtarea | F23: Status | G23: Responsable | H23: Fecha Límite | I23: Comentarios
C24: =FALSE() -> FALSE | D24: E2-003 | E24: Definir modelo de dato de autorización previa | F24: Completado | G24: Fernando
C25: =FALSE() -> FALSE | D25: E2-003 | E25: Configurar búsqueda de autorizaciones en ECM | F25: En Revisión
C26: =FALSE() -> FALSE | D26: E2-003 | E26: Configurar regla de alerta por procedimiento sin autorización | F26: Completado | G26: Fernando
C27: =FALSE() -> FALSE | D27: E2-003 | E27: Pruebas con casos con y sin autorización | F27: Completado | G27: Fernando
C29: =FALSE() -> FALSE | D29: E2-004 | E29: Comparación con tarifas del convenio | F29: Valida que los montos facturados estén dentro del rango tarifario pactado | G29: Agente IA + KD | H29: CRÍTICA | I29: En Progreso | M29: =COUNTA(E31:E83) -> 27 | N29: =COUNTIF(F31:F83,"Completado") -> 9 | O29: =IFERROR(COUNTIF(F31:F34,"Completado")/COUNTA(E31:E34),0) -> 0.75 | P29: Avanzo la configuración de automate y agent builder creando 3 agentes paralelos, están funcionando parcialmente por errores de agent builder.
B30: ☑ | C30: ✓ | D30: ↳ Epic | E30: Subtarea | F30: Status | G30: Responsable | H30: Fecha Límite | I30: Comentarios
C31: =FALSE() -> FALSE | D31: E2-004 | E31: Cargar tarifarios por aseguradora | F31: Completado | G31: Fernando
C32: =FALSE() -> FALSE | D32: E2-004 | E32: Configurar comparación de montos por procedimiento | F32: Completado | G32: Fernando
C33: =FALSE() -> FALSE | D33: E2-004 | E33: Definir tolerancia de variación permitida | F33: Completado | G33: Fernando
C34: =FALSE() -> FALSE | D34: E2-004 | E34: Pruebas con cuentas de diferente aseguradora | F34: En Progreso | I34: Solo tenemos la cuenta de
C36: =FALSE() -> FALSE | D36: E2-005 | E36: Informe de pre-validación con sugerencias | F36: Genera un reporte con los hallazgos, nivel de riesgo y acciones de corrección | G36: Agente IA | H36: CRÍTICA | I36: En Progreso | M36: =COUNTA(E38:E90) -> 21 | N36: =COUNTIF(F38:F90,"Completado") -> 6 | O36: =IFERROR(COUNTIF(F38:F40,"Completado")/COUNTA(E38:E40),0) -> 1 | P36: Se avanzo en una primera version de la UI Custom, esta en localhost.
B37: ☑ | C37: ✓ | D37: ↳ Epic | E37: Subtarea | F37: Status | G37: Responsable | H37: Fecha Límite | I37: Comentarios
C38: =FALSE() -> FALSE | D38: E2-005 | E38: Diseñar template del informe de pre-validación | F38: Completado | G38: Fernando
C39: =FALSE() -> FALSE | D39: E2-005 | E39: Configurar generación automática del reporte | F39: Completado | G39: Fernando | I39: Se genera unn widget para el formulario de analisis donde se ve el reporte de las Ias
C40: =FALSE() -> FALSE | D40: E2-005 | E40: Definir niveles de severidad de hallazgos | F40: Completado | G40: Fernando
C42: =FALSE() -> FALSE | D42: E2-006 | E42: Aprendizaje de patrones históricos de glosa | F42: El agente consulta el historial de glosas para anticipar objeciones recurrentes | G42: Knowledge Discovery | H42: CRÍTICA | I42: =IF(C42,"Completado","Pendiente") -> Pendiente | M42: =COUNTA(E44:E97) -> 16 | N42: =COUNTIF(F44:F97,"Completado") -> 3 | O42: =IFERROR(COUNTIF(F44:F97,"Completado")/COUNTA(E44:E97),0) -> 0.1875
B43: ☑ | C43: ✓ | D43: ↳ Epic | E43: Subtarea | F43: Status | G43: Responsable | H43: Fecha Límite | I43: Comentarios
C44: =FALSE() -> FALSE | D44: E2-006 | E44: Cargar histórico de glosas del cliente (mínimo 12 meses) | F44: =IF(C44,"Completado","Pendiente") -> Pendiente
C45: =FALSE() -> FALSE | D45: E2-006 | E45: Configurar indexación de patrones por aseguradora y código | F45: =IF(C45,"Completado","Pendiente") -> Pendiente
C46: =FALSE() -> FALSE | D46: E2-006 | E46: Validar consulta de precedentes desde el agente | F46: =IF(C46,"Completado","Pendiente") -> Pendiente
...

Sheet E3 · Envío
A2: HYLAND | Cuentas Médicas — Prestadores de Servicios
A3: Etapa 3 — Armado y Envío de la Cuenta
A4: Con el expediente validado, el sistema arma el paquete de envío en el formato exigido por cada aseguradora y lo envía de forma trazable. El prestador puede manejar múltiples aseguradoras con formatos distintos desde una única plataforma.
B6: ☑ | C6: ✓ | D6: Epic ID | E6: Nombre del Epic | F6: Descripción | G6: Módulo Hyland | H6: Prioridad | I6: Status | J6: Responsable | K6: Fecha Inicio | L6: Fecha Límite | M6: Subtareas | N6: Completadas | O6: % Avance | P6: Comentarios / Bloqueantes
C7: =FALSE() -> FALSE | D7: E3-001 | E7: Generación de RIPS automática | F7: Arma el archivo RIPS en el formato requerido a partir del expediente estructurado | G7: Automate + ECM | H7: CRÍTICA | I7: =IF(C7,"Completado","Pendiente") -> Pendiente | M7: =COUNTA(E9:E62) -> 35 | N7: =COUNTIF(F9:F62,"Completado") -> 0 | O7: =IFERROR(COUNTIF(F9:F62,"Completado")/COUNTA(E9:E62),0) -> 0
B8: ☑ | C8: ✓ | D8: ↳ Epic | E8: Subtarea | F8: Status | G8: Responsable | H8: Fecha Límite | I8: Comentarios
C9: =FALSE() -> FALSE | D9: E3-001 | E9: Mapear campos del expediente al estándar RIPS | F9: =IF(C9,"Completado","Pendiente") -> Pendiente
C10: =FALSE() -> FALSE | D10: E3-001 | E10: Configurar generación de archivo RIPS en Automate | F10: =IF(C10,"Completado","Pendiente") -> Pendiente
C11: =FALSE() -> FALSE | D11: E3-001 | E11: Validar RIPS con validador oficial | F11: =IF(C11,"Completado","Pendiente") -> Pendiente
C12: =FALSE() -> FALSE | D12: E3-001 | E12: Pruebas con múltiples tipos de evento | F12: =IF(C12,"Completado","Pendiente") -> Pendiente
C14: =FALSE() -> FALSE | D14: E3-002 | E14: Soporte multi-formato de envío | F14: Adapta el paquete a XML FHIR, EDI, RIPS o formato propietario según el convenio | G14: Automate | H14: CRÍTICA | I14: =IF(C14,"Completado","Pendiente") -> Pendiente | M14: =COUNTA(E16:E69) -> 29 | N14: =COUNTIF(F16:F69,"Completado") -> 0 | O14: =IFERROR(COUNTIF(F16:F69,"Completado")/COUNTA(E16:E69),0) -> 0
B15: ☑ | C15: ✓ | D15: ↳ Epic | E15: Subtarea | F15: Status | G15: Responsable | H15: Fecha Límite | I15: Comentarios
C16: =FALSE() -> FALSE | D16: E3-002 | E16: Catalogar formatos requeridos por cada aseguradora | F16: =IF(C16,"Completado","Pendiente") -> Pendiente
C17: =FALSE() -> FALSE | D17: E3-002 | E17: Configurar transformadores de formato en Automate | F17: =IF(C17,"Completado","Pendiente") -> Pendiente
C18: =FALSE() -> FALSE | D18: E3-002 | E18: Pruebas de generación por formato | F18: =IF(C18,"Completado","Pendiente") -> Pendiente
C19: =FALSE() -> FALSE | D19: E3-002 | E19: Validación con aseguradoras del cliente | F19: =IF(C19,"Completado","Pendiente") -> Pendiente
C21: =FALSE() -> FALSE | D21: E3-003 | E21: Registro de trazabilidad de envío | F21: Guarda fecha, hora, canal, destinatario y número de radicado como evidencia legal | G21: ECM | H21: CRÍTICA | I21: =IF(C21,"Completado","Pendiente") -> Pendiente | M21: =COUNTA(E23:E76) -> 23 | N21: =COUNTIF(F23:F76,"Completado") -> 0 | O21: =IFERROR(COUNTIF(F23:F76,"Completado")/COUNTA(E23:E76),0) -> 0
B22: ☑ | C22: ✓ | D22: ↳ Epic | E22: Subtarea | F22: Status | G22: Responsable | H22: Fecha Límite | I22: Comentarios
C23: =FALSE() -> FALSE | D23: E3-003 | E23: Definir campos de metadatos de trazabilidad | F23: =IF(C23,"Completado","Pendiente") -> Pendiente
C24: =FALSE() -> FALSE | D24: E3-003 | E24: Configurar escritura automática de log en ECM | F24: =IF(C24,"Completado","Pendiente") -> Pendiente
C25: =FALSE() -> FALSE | D25: E3-003 | E25: Validar inmutabilidad del registro | F25: =IF(C25,"Completado","Pendiente") -> Pendiente
C26: =FALSE() -> FALSE | D26: E3-003 | E26: Pruebas de auditoría | F26: =IF(C26,"Completado","Pendiente") -> Pendiente
C28: =FALSE() -> FALSE | D28: E3-004 | E28: Gestión de portales de aseguradoras | F28: Automatiza el logín y subida de documentos a portales web sin API mediante RPA | G28: Automate (RPA) | H28: MEDIA | I28: =IF(C28,"Completado","Pendiente") -> Pendiente | M28: =COUNTA(E30:E83) -> 17 | N28: =COUNTIF(F30:F83,"Completado") -> 0 | O28: =IFERROR(COUNTIF(F30:F83,"Completado")/COUNTA(E30:E83),0) -> 0
B29: ☑ | C29: ✓ | D29: ↳ Epic | E29: Subtarea | F29: Status | G29: Responsable | H29: Fecha Límite | I29: Comentarios
C30: =FALSE() -> FALSE | D30: E3-004 | E30: Inventariar portales de aseguradoras del cliente | F30: =IF(C30,"Completado","Pendiente") -> Pendiente
C31: =FALSE() -> FALSE | D31: E3-004 | E31: Desarrollar bots RPA por portal | F31: =IF(C31,"Completado","Pendiente") -> Pendiente
C32: =FALSE() -> FALSE | D32: E3-004 | E32: Pruebas de estabilidad de bots | F32: =IF(C32,"Completado","Pendiente") -> Pendiente
C33: =FALSE() -> FALSE | D33: E3-004 | E33: Definir mantenimiento ante cambios de interfaz | F33: =IF(C33,"Completado","Pendiente") -> Pendiente
C35: =FALSE() -> FALSE | D35: E3-005 | E35: Panel de seguimiento de envíos | F35: Dashboard con estado de todas las cuentas enviadas | G35: ECM / CIC | H35: MEDIA | I35: =IF(C35,"Completado","Pendiente") -> Pendiente | M35: =COUNTA(E37:E90) -> 11 | N35: =COUNTIF(F37:F90,"Completado") -> 0 | O35: =IFERROR(COUNTIF(F37:F90,"Completado")/COUNTA(E37:E90),0) -> 0
B36: ☑ | C36: ✓ | D36: ↳ Epic | E36: Subtarea | F36: Status | G36: Responsable | H36: Fecha Límite | I36: Comentarios
C37: =FALSE() -> FALSE | D37: E3-005 | E37: Definir KPIs del panel con el cliente | F37: =IF(C37,"Completado","Pendiente") -> Pendiente
C38: =FALSE() -> FALSE | D38: E3-005 | E38: Configurar vistas en ECM/CIC | F38: =IF(C38,"Completado","Pendiente") -> Pendiente
C39: =FALSE() -> FALSE | D39: E3-005 | E39: Pruebas de actualización en tiempo real | F39: =IF(C39,"Completado","Pendiente") -> Pendiente
C40: =FALSE() -> FALSE | D40: E3-005 | E40: Capacitación al equipo de facturación | F40: =IF(C40,"Completado","Pendiente") -> Pendiente
C42: =FALSE() -> FALSE | D42: E3-006 | E42: Gestión de reenvíos por rechazo técnico | F42: Si la aseguradora rechaza el envío, el sistema corrige y reenvía automáticamente | G42: Automate | H42: MEDIA | I42: =IF(C42,"Completado","Pendiente") -> Pendiente | M42: =COUNTA(E44:E97) -> 5 | N42: =COUNTIF(F44:F97,"Completado") -> 0 | O42: =IFERROR(COUNTIF(F44:F97,"Completado")/COUNTA(E44:E97),0) -> 0
B43: ☑ | C43: ✓ | D43: ↳ Epic | E43: Subtarea | F43: Status | G43: Responsable | H43: Fecha Límite | I43: Comentarios
C44: =FALSE() -> FALSE | D44: E3-006 | E44: Mapear tipos de rechazo técnico por aseguradora | F44: =IF(C44,"Completado","Pendiente") -> Pendiente
C45: =FALSE() -> FALSE | D45: E3-006 | E45: Configurar lógica de autocorrección en Automate | F45: =IF(C45,"Completado","Pendiente") -> Pendiente
C46: =FALSE() -> FALSE | D46: E3-006 | E46: Definir límite de reintentos y escalación | F46: =IF(C46,"Completado","Pendiente") -> Pendiente
C47: =FALSE() -> FALSE | D47: E3-006 | E47: Pruebas de escenarios de rechazo | F47: =IF(C47,"Completado","Pendiente") -> Pendiente
...

Sheet E4 · Glosas
A2: HYLAND | Cuentas Médicas — Prestadores de Servicios
A3: Etapa 4 — Recepción y Gestión de Glosas
A4: La aseguradora devuelve la cuenta con glosas parciales o totales. El sistema las recibe, las vincula al expediente y abre un caso de gestión. El equipo cuenta con inteligencia histórica para decidir si aceptar o apelar.
B6: ☑ | C6: ✓ | D6: Epic ID | E6: Nombre del Epic | F6: Descripción | G6: Módulo Hyland | H6: Prioridad | I6: Status | J6: Responsable | K6: Fecha Inicio | L6: Fecha Límite | M6: Subtareas | N6: Completadas | O6: % Avance | P6: Comentarios / Bloqueantes
C7: =FALSE() -> FALSE | D7: E4-001 | E7: Recepción automática de respuestas de glosa | F7: Captura la respuesta de la aseguradora y la vincula al expediente original | G7: IDP + Automate | H7: CRÍTICA | I7: =IF(C7,"Completado","Pendiente") -> Pendiente | M7: =COUNTA(E9:E62) -> 45 | N7: =COUNTIF(F9:F62,"Completado") -> 0 | O7: =IFERROR(COUNTIF(F9:F62,"Completado")/COUNTA(E9:E62),0) -> 0
B8: ☑ | C8: ✓ | D8: ↳ Epic | E8: Subtarea | F8: Status | G8: Responsable | H8: Fecha Límite | I8: Comentarios
C9: =FALSE() -> FALSE | D9: E4-001 | E9: Configurar captura de glosas por email | F9: =IF(C9,"Completado","Pendiente") -> Pendiente
C10: =FALSE() -> FALSE | D10: E4-001 | E10: Configurar captura de glosas por portal | F10: =IF(C10,"Completado","Pendiente") -> Pendiente
C11: =FALSE() -> FALSE | D11: E4-001 | E11: Configurar captura por EDI | F11: =IF(C11,"Completado","Pendiente") -> Pendiente
C12: =FALSE() -> FALSE | D12: E4-001 | E12: Validar vinculación automática al expediente | F12: =IF(C12,"Completado","Pendiente") -> Pendiente
C14: =FALSE() -> FALSE | D14: E4-002 | E14: Apertura automática de caso de glosa | F14: Cada glosa genera un caso en Case Management asignado al auditor responsable | G14: Case Management | H14: CRÍTICA | I14: =IF(C14,"Completado","Pendiente") -> Pendiente | M14: =COUNTA(E16:E69) -> 39 | N14: =COUNTIF(F16:F69,"Completado") -> 0 | O14: =IFERROR(COUNTIF(F16:F69,"Completado")/COUNTA(E16:E69),0) -> 0
B15: ☑ | C15: ✓ | D15: ↳ Epic | E15: Subtarea | F15: Status | G15: Responsable | H15: Fecha Límite | I15: Comentarios
C16: =FALSE() -> FALSE | D16: E4-002 | E16: Configurar template de caso de glosa | F16: =IF(C16,"Completado","Pendiente") -> Pendiente
C17: =FALSE() -> FALSE | D17: E4-002 | E17: Definir reglas de asignación automática | F17: =IF(C17,"Completado","Pendiente") -> Pendiente
C18: =FALSE() -> FALSE | D18: E4-002 | E18: Configurar notificación al auditor responsable | F18: =IF(C18,"Completado","Pendiente") -> Pendiente
C19: =FALSE() -> FALSE | D19: E4-002 | E19: Pruebas de apertura automática end-to-end | F19: =IF(C19,"Completado","Pendiente") -> Pendiente
C21: =FALSE() -> FALSE | D21: E4-003 | E21: Análisis de recurrencia con Knowledge Discovery | F21: Muestra si la misma glosa se ha recibido antes y cuál fue el resultado al apelar | G21: Knowledge Discovery | H21: CRÍTICA | I21: =IF(C21,"Completado","Pendiente") -> Pendiente | M21: =COUNTA(E23:E76) -> 33 | N21: =COUNTIF(F23:F76,"Completado") -> 0 | O21: =IFERROR(COUNTIF(F23:F76,"Completado")/COUNTA(E23:E76),0) -> 0
B22: ☑ | C22: ✓ | D22: ↳ Epic | E22: Subtarea | F22: Status | G22: Responsable | H22: Fecha Límite | I22: Comentarios
C23: =FALSE() -> FALSE | D23: E4-003 | E23: Configurar indexación de glosas por código y aseguradora | F23: =IF(C23,"Completado","Pendiente") -> Pendiente
C24: =FALSE() -> FALSE | D24: E4-003 | E24: Configurar panel de recurrencia en el caso | F24: =IF(C24,"Completado","Pendiente") -> Pendiente
C25: =FALSE() -> FALSE | D25: E4-003 | E25: Calcular tasa histórica de éxito en apelación | F25: =IF(C25,"Completado","Pendiente") -> Pendiente
C26: =FALSE() -> FALSE | D26: E4-003 | E26: Validar con auditor de referencia del cliente | F26: =IF(C26,"Completado","Pendiente") -> Pendiente
C28: =FALSE() -> FALSE | D28: E4-004 | E28: Dashboard de glosas por aseguradora y código | F28: Visualización agregada de glosas por aseguradora, tipo y valor objetado | G28: ECM / CIC | H28: CRÍTICA | I28: =IF(C28,"Completado","Pendiente") -> Pendiente | M28: =COUNTA(E30:E83) -> 27 | N28: =COUNTIF(F30:F83,"Completado") -> 0 | O28: =IFERROR(COUNTIF(F30:F83,"Completado")/COUNTA(E30:E83),0) -> 0
B29: ☑ | C29: ✓ | D29: ↳ Epic | E29: Subtarea | F29: Status | G29: Responsable | H29: Fecha Límite | I29: Comentarios
C30: =FALSE() -> FALSE | D30: E4-004 | E30: Definir dimensiones de análisis con el cliente | F30: =IF(C30,"Completado","Pendiente") -> Pendiente
C31: =FALSE() -> FALSE | D31: E4-004 | E31: Configurar dashboard en ECM/CIC | F31: =IF(C31,"Completado","Pendiente") -> Pendiente
C32: =FALSE() -> FALSE | D32: E4-004 | E32: Configurar actualización automática | F32: =IF(C32,"Completado","Pendiente") -> Pendiente
C33: =FALSE() -> FALSE | D33: E4-004 | E33: Capacitación a gerencia de facturación | F33: =IF(C33,"Completado","Pendiente") -> Pendiente
C35: =FALSE() -> FALSE | D35: E4-005 | E35: Alertas de vencimiento de plazo de respuesta | F35: Notificaciones automáticas cuando se acerca el plazo legal para responder | G35: Automate | H35: CRÍTICA | I35: =IF(C35,"Completado","Pendiente") -> Pendiente | M35: =COUNTA(E37:E90) -> 21 | N35: =COUNTIF(F37:F90,"Completado") -> 0 | O35: =IFERROR(COUNTIF(F37:F90,"Completado")/COUNTA(E37:E90),0) -> 0
B36: ☑ | C36: ✓ | D36: ↳ Epic | E36: Subtarea | F36: Status | G36: Responsable | H36: Fecha Límite | I36: Comentarios
C37: =FALSE() -> FALSE | D37: E4-005 | E37: Mapear plazos legales por aseguradora y país | F37: =IF(C37,"Completado","Pendiente") -> Pendiente
C38: =FALSE() -> FALSE | D38: E4-005 | E38: Configurar cálculo de fecha límite en Automate | F38: =IF(C38,"Completado","Pendiente") -> Pendiente
C39: =FALSE() -> FALSE | D39: E4-005 | E39: Configurar alertas T-5, T-2 y T-0 días | F39: =IF(C39,"Completado","Pendiente") -> Pendiente
C40: =FALSE() -> FALSE | D40: E4-005 | E40: Pruebas de escalación ante inacción | F40: =IF(C40,"Completado","Pendiente") -> Pendiente
C42: =FALSE() -> FALSE | D42: E4-006 | E42: Clasificación de glosas por tipo | F42: Categoriza automáticamente la glosa: técnica, administrativa, documental o de cobertura | G42: Agente IA + IDP | H42: MEDIA | I42: =IF(C42,"Completado","Pendiente") -> Pendiente | M42: =COUNTA(E44:E96) -> 15 | N42: =COUNTIF(F44:F96,"Completado") -> 0 | O42: =IFERROR(COUNTIF(F44:F96,"Completado")/COUNTA(E44:E96),0) -> 0
B43: ☑ | C43: ✓ | D43: ↳ Epic | E43: Subtarea | F43: Status | G43: Responsable | H43: Fecha Límite | I43: Comentarios
C44: =FALSE() -> FALSE | D44: E4-006 | E44: Definir taxonomía de tipos de glosa | F44: =IF(C44,"Completado","Pendiente") -> Pendiente
C45: =FALSE() -> FALSE | D45: E4-006 | E45: Configurar clasificador en el agente IA | F45: =IF(C45,"Completado","Pendiente") -> Pendiente
C46: =FALSE() -> FALSE | D46: E4-006 | E46: Pruebas de precisión de clasificación | F46: =IF(C46,"Completado","Pendiente") -> Pendiente
C48: =FALSE() -> FALSE | D48: E4-007 | E48: Cálculo de impacto financiero en tiempo real | F48: Calcula el monto total objetado, en apelación y la proyección de recupero | G48: ECM / CIC | H48: MEDIA | I48: =IF(C48,"Completado","Pendiente") -> Pendiente | M48: =COUNTA(E50:E102) -> 10 | N48: =COUNTIF(F50:F102,"Completado") -> 0 | O48: =IFERROR(COUNTIF(F50:F102,"Completado")/COUNTA(E50:E102),0) -> 0
...

Sheet E5 · Apelación
A2: HYLAND | Cuentas Médicas — Prestadores de Servicios
A3: Etapa 5 — Respuesta y Apelación de Glosas
A4: El prestador decide apelar la glosa. El Agente IA ayuda a construir el argumento de respuesta, identificando documentos de soporte relevantes y sugiriendo el texto de justificación basado en casos similares resueltos exitosamente.
B6: ☑ | C6: ✓ | D6: Epic ID | E6: Nombre del Epic | F6: Descripción | G6: Módulo Hyland | H6: Prioridad | I6: Status | J6: Responsable | K6: Fecha Inicio | L6: Fecha Límite | M6: Subtareas | N6: Completadas | O6: % Avance | P6: Comentarios / Bloqueantes
C7: =FALSE() -> FALSE | D7: E5-001 | E7: Asistencia del Agente IA para construir la apelación | F7: El agente identifica documentos, sugiere el argumento y redacta el borrador de respuesta | G7: Agente IA + KD | H7: CRÍTICA | I7: =IF(C7,"Completado","Pendiente") -> Pendiente | M7: =COUNTA(E9:E62) -> 33 | N7: =COUNTIF(F9:F62,"Completado") -> 0 | O7: =IFERROR(COUNTIF(F9:F62,"Completado")/COUNTA(E9:E62),0) -> 0
B8: ☑ | C8: ✓ | D8: ↳ Epic | E8: Subtarea | F8: Status | G8: Responsable | H8: Fecha Límite | I8: Comentarios
C9: =FALSE() -> FALSE | D9: E5-001 | E9: Configurar recuperación de documentos relevantes del expediente | F9: =IF(C9,"Completado","Pendiente") -> Pendiente
C10: =FALSE() -> FALSE | D10: E5-001 | E10: Configurar generación de borrador de apelación | F10: =IF(C10,"Completado","Pendiente") -> Pendiente
C11: =FALSE() -> FALSE | D11: E5-001 | E11: Integrar precedentes exitosos del KD al borrador | F11: =IF(C11,"Completado","Pendiente") -> Pendiente
C12: =FALSE() -> FALSE | D12: E5-001 | E12: Validación con auditor senior del cliente | F12: =IF(C12,"Completado","Pendiente") -> Pendiente
C14: =FALSE() -> FALSE | D14: E5-002 | E14: Búsqueda de precedentes exitosos | F14: Recupera casos similares donde la apelación fue aceptada con los argumentos que funcionaron | G14: Knowledge Discovery | H14: CRÍTICA | I14: =IF(C14,"Completado","Pendiente") -> Pendiente | M14: =COUNTA(E16:E69) -> 27 | N14: =COUNTIF(F16:F69,"Completado") -> 0 | O14: =IFERROR(COUNTIF(F16:F69,"Completado")/COUNTA(E16:E69),0) -> 0
B15: ☑ | C15: ✓ | D15: ↳ Epic | E15: Subtarea | F15: Status | G15: Responsable | H15: Fecha Límite | I15: Comentarios
C16: =FALSE() -> FALSE | D16: E5-002 | E16: Configurar indexación de apelaciones resueltas | F16: =IF(C16,"Completado","Pendiente") -> Pendiente
C17: =FALSE() -> FALSE | D17: E5-002 | E17: Definir criterios de similitud para recuperación | F17: =IF(C17,"Completado","Pendiente") -> Pendiente
C18: =FALSE() -> FALSE | D18: E5-002 | E18: Configurar ranking por tasa de éxito | F18: =IF(C18,"Completado","Pendiente") -> Pendiente
C19: =FALSE() -> FALSE | D19: E5-002 | E19: Pruebas de relevancia de resultados | F19: =IF(C19,"Completado","Pendiente") -> Pendiente
C21: =FALSE() -> FALSE | D21: E5-003 | E21: Gestión del flujo de aprobación interna | F21: La respuesta pasa por revisión y aprobación antes del envío, con firma electrónica | G21: Automate + ECM | H21: CRÍTICA | I21: =IF(C21,"Completado","Pendiente") -> Pendiente | M21: =COUNTA(E23:E76) -> 21 | N21: =COUNTIF(F23:F76,"Completado") -> 0 | O21: =IFERROR(COUNTIF(F23:F76,"Completado")/COUNTA(E23:E76),0) -> 0
B22: ☑ | C22: ✓ | D22: ↳ Epic | E22: Subtarea | F22: Status | G22: Responsable | H22: Fecha Límite | I22: Comentarios
C23: =FALSE() -> FALSE | D23: E5-003 | E23: Diseñar flujo de aprobación multinivel | F23: =IF(C23,"Completado","Pendiente") -> Pendiente
C24: =FALSE() -> FALSE | D24: E5-003 | E24: Configurar workflow en Automate | F24: =IF(C24,"Completado","Pendiente") -> Pendiente
C25: =FALSE() -> FALSE | D25: E5-003 | E25: Integrar firma electrónica si aplica | F25: =IF(C25,"Completado","Pendiente") -> Pendiente
C26: =FALSE() -> FALSE | D26: E5-003 | E26: Pruebas de flujo completo de aprobación | F26: =IF(C26,"Completado","Pendiente") -> Pendiente
C28: =FALSE() -> FALSE | D28: E5-004 | E28: Envío trazable de la apelación | F28: El envío queda registrado con fecha, hora y acuse de recibo en el expediente | G28: Automate + ECM | H28: CRÍTICA | I28: =IF(C28,"Completado","Pendiente") -> Pendiente | M28: =COUNTA(E30:E82) -> 15 | N28: =COUNTIF(F30:F82,"Completado") -> 0 | O28: =IFERROR(COUNTIF(F30:F82,"Completado")/COUNTA(E30:E82),0) -> 0
B29: ☑ | C29: ✓ | D29: ↳ Epic | E29: Subtarea | F29: Status | G29: Responsable | H29: Fecha Límite | I29: Comentarios
C30: =FALSE() -> FALSE | D30: E5-004 | E30: Configurar envío automático con registro en ECM | F30: =IF(C30,"Completado","Pendiente") -> Pendiente
C31: =FALSE() -> FALSE | D31: E5-004 | E31: Configurar captura del acuse de recibo | F31: =IF(C31,"Completado","Pendiente") -> Pendiente
C32: =FALSE() -> FALSE | D32: E5-004 | E32: Validar inmutabilidad del registro de envío | F32: =IF(C32,"Completado","Pendiente") -> Pendiente
C34: =FALSE() -> FALSE | D34: E5-005 | E34: Seguimiento del estado de la apelación | F34: Panel con estado de cada apelación: pendiente, aceptada, rechazada, en conciliación | G34: Case Management | H34: CRÍTICA | I34: =IF(C34,"Completado","Pendiente") -> Pendiente | M34: =COUNTA(E36:E89) -> 10 | N34: =COUNTIF(F36:F89,"Completado") -> 0 | O34: =IFERROR(COUNTIF(F36:F89,"Completado")/COUNTA(E36:E89),0) -> 0
B35: ☑ | C35: ✓ | D35: ↳ Epic | E35: Subtarea | F35: Status | G35: Responsable | H35: Fecha Límite | I35: Comentarios
C36: =FALSE() -> FALSE | D36: E5-005 | E36: Configurar estados del caso de apelación | F36: =IF(C36,"Completado","Pendiente") -> Pendiente
C37: =FALSE() -> FALSE | D37: E5-005 | E37: Configurar panel de seguimiento | F37: =IF(C37,"Completado","Pendiente") -> Pendiente
C38: =FALSE() -> FALSE | D38: E5-005 | E38: Configurar alertas de cambio de estado | F38: =IF(C38,"Completado","Pendiente") -> Pendiente
C39: =FALSE() -> FALSE | D39: E5-005 | E39: Capacitación al equipo auditor | F39: =IF(C39,"Completado","Pendiente") -> Pendiente
C41: =FALSE() -> FALSE | D41: E5-006 | E41: Enriquecimiento de la base de conocimiento | F41: Cada glosa resuelta alimenta automáticamente el Knowledge Discovery | G41: Knowledge Discovery | H41: MEDIA | I41: =IF(C41,"Completado","Pendiente") -> Pendiente | M41: =COUNTA(E43:E95) -> 4 | N41: =COUNTIF(F43:F95,"Completado") -> 0 | O41: =IFERROR(COUNTIF(F43:F95,"Completado")/COUNTA(E43:E95),0) -> 0
B42: ☑ | C42: ✓ | D42: ↳ Epic | E42: Subtarea | F42: Status | G42: Responsable | H42: Fecha Límite | I42: Comentarios
C43: =FALSE() -> FALSE | D43: E5-006 | E43: Configurar pipeline de retroalimentación al KD | F43: =IF(C43,"Completado","Pendiente") -> Pendiente
C44: =FALSE() -> FALSE | D44: E5-006 | E44: Definir metadatos de resultado a capturar | F44: =IF(C44,"Completado","Pendiente") -> Pendiente
C45: =FALSE() -> FALSE | D45: E5-006 | E45: Validar actualización de tasa de éxito | F45: =IF(C45,"Completado","Pendiente") -> Pendiente
A47: Resumen de Etapa | E47: ="6 Epics | "&SUMPRODUCT((E7:E45<>"")*1)&" Subtareas activas" -> 6 Epics | 34 Subtareas activas | N47: =COUNTIF(F7:F45,"Completado") -> 0 | O47: =IFERROR(COUNTIF(F7:F45,"Completado")/COUNTA(E7:E45),0) -> 0

Sheet E6 · Pago y Cierre
A2: HYLAND | Cuentas Médicas — Prestadores de Servicios
A3: Etapa 6 — Seguimiento de Pago, Conciliación y Cierre
A4: La aseguradora emite el pago. El sistema reconcilia el valor recibido contra la cuenta original y los acuerdos de glosa, cierra el expediente con trazabilidad completa y alimenta la inteligencia para futuros procesos.
B6: ☑ | C6: ✓ | D6: Epic ID | E6: Nombre del Epic | F6: Descripción | G6: Módulo Hyland | H6: Prioridad | I6: Status | J6: Responsable | K6: Fecha Inicio | L6: Fecha Límite | M6: Subtareas | N6: Completadas | O6: % Avance | P6: Comentarios / Bloqueantes
C7: =FALSE() -> FALSE | D7: E6-001 | E7: Conciliación automática de pagos | F7: Cruza el valor pagado contra la cuenta original y los acuerdos de glosa | G7: Automate + ECM | H7: CRÍTICA | I7: =IF(C7,"Completado","Pendiente") -> Pendiente | M7: =COUNTA(E9:E62) -> 40 | N7: =COUNTIF(F9:F62,"Completado") -> 0 | O7: =IFERROR(COUNTIF(F9:F62,"Completado")/COUNTA(E9:E62),0) -> 0
B8: ☑ | C8: ✓ | D8: ↳ Epic | E8: Subtarea | F8: Status | G8: Responsable | H8: Fecha Límite | I8: Comentarios
C9: =FALSE() -> FALSE | D9: E6-001 | E9: Definir reglas de conciliación por tipo de acuerdo | F9: =IF(C9,"Completado","Pendiente") -> Pendiente
C10: =FALSE() -> FALSE | D10: E6-001 | E10: Configurar proceso de conciliación en Automate | F10: =IF(C10,"Completado","Pendiente") -> Pendiente
C11: =FALSE() -> FALSE | D11: E6-001 | E11: Configurar alerta por diferencias no esperadas | F11: =IF(C11,"Completado","Pendiente") -> Pendiente
C12: =FALSE() -> FALSE | D12: E6-001 | E12: Pruebas con escenarios de pago parcial | F12: =IF(C12,"Completado","Pendiente") -> Pendiente
C14: =FALSE() -> FALSE | D14: E6-002 | E14: Cierre del expediente con trazabilidad completa | F14: El expediente queda cerrado con el historial completo: facturación, glosas, apelaciones, pago | G14: ECM | H14: CRÍTICA | I14: =IF(C14,"Completado","Pendiente") -> Pendiente | M14: =COUNTA(E16:E69) -> 34 | N14: =COUNTIF(F16:F69,"Completado") -> 0 | O14: =IFERROR(COUNTIF(F16:F69,"Completado")/COUNTA(E16:E69),0) -> 0
B15: ☑ | C15: ✓ | D15: ↳ Epic | E15: Subtarea | F15: Status | G15: Responsable | H15: Fecha Límite | I15: Comentarios
C16: =FALSE() -> FALSE | D16: E6-002 | E16: Definir checklist de cierre del expediente | F16: =IF(C16,"Completado","Pendiente") -> Pendiente
C17: =FALSE() -> FALSE | D17: E6-002 | E17: Configurar sellado del expediente al cierre | F17: =IF(C17,"Completado","Pendiente") -> Pendiente
C18: =FALSE() -> FALSE | D18: E6-002 | E18: Validar trazabilidad completa del timeline | F18: =IF(C18,"Completado","Pendiente") -> Pendiente
C19: =FALSE() -> FALSE | D19: E6-002 | E19: Pruebas de acceso post-cierre (solo lectura) | F19: =IF(C19,"Completado","Pendiente") -> Pendiente
C21: =FALSE() -> FALSE | D21: E6-003 | E21: Dashboard financiero de recupero | F21: Muestra por aseguradora: valor facturado, glosado, recuperado y perdido definitivamente | G21: ECM / CIC | H21: CRÍTICA | I21: =IF(C21,"Completado","Pendiente") -> Pendiente | M21: =COUNTA(E23:E76) -> 28 | N21: =COUNTIF(F23:F76,"Completado") -> 0 | O21: =IFERROR(COUNTIF(F23:F76,"Completado")/COUNTA(E23:E76),0) -> 0
B22: ☑ | C22: ✓ | D22: ↳ Epic | E22: Subtarea | F22: Status | G22: Responsable | H22: Fecha Límite | I22: Comentarios
C23: =FALSE() -> FALSE | D23: E6-003 | E23: Definir métricas de recupero con el cliente | F23: =IF(C23,"Completado","Pendiente") -> Pendiente
C24: =FALSE() -> FALSE | D24: E6-003 | E24: Configurar dashboard financiero en ECM/CIC | F24: =IF(C24,"Completado","Pendiente") -> Pendiente
C25: =FALSE() -> FALSE | D25: E6-003 | E25: Configurar exportación a Excel/PDF | F25: =IF(C25,"Completado","Pendiente") -> Pendiente
C26: =FALSE() -> FALSE | D26: E6-003 | E26: Capacitación a dirección financiera | F26: =IF(C26,"Completado","Pendiente") -> Pendiente
C28: =FALSE() -> FALSE | D28: E6-004 | E28: Integración con ERP y cuentas por cobrar | F28: El cierre del expediente actualiza automáticamente el sistema contable del prestador | G28: Automate + Integraciones | H28: CRÍTICA | I28: =IF(C28,"Completado","Pendiente") -> Pendiente | M28: =COUNTA(E30:E83) -> 22 | N28: =COUNTIF(F30:F83,"Completado") -> 0 | O28: =IFERROR(COUNTIF(F30:F83,"Completado")/COUNTA(E30:E83),0) -> 0
B29: ☑ | C29: ✓ | D29: ↳ Epic | E29: Subtarea | F29: Status | G29: Responsable | H29: Fecha Límite | I29: Comentarios
C30: =FALSE() -> FALSE | D30: E6-004 | E30: Mapear eventos de cierre a acciones en ERP | F30: =IF(C30,"Completado","Pendiente") -> Pendiente
C31: =FALSE() -> FALSE | D31: E6-004 | E31: Desarrollar conector de integración ERP | F31: =IF(C31,"Completado","Pendiente") -> Pendiente
C32: =FALSE() -> FALSE | D32: E6-004 | E32: Pruebas de consistencia contable end-to-end | F32: =IF(C32,"Completado","Pendiente") -> Pendiente
C33: =FALSE() -> FALSE | D33: E6-004 | E33: Validación con auditoría financiera del cliente | F33: =IF(C33,"Completado","Pendiente") -> Pendiente
C35: =FALSE() -> FALSE | D35: E6-005 | E35: Métricas de ciclo de cuentas médicas | F35: Tiempo promedio de pago, tasa de glosas, tasa de éxito en apelación, valor en riesgo | G35: ECM / CIC | H35: CRÍTICA | I35: =IF(C35,"Completado","Pendiente") -> Pendiente | M35: =COUNTA(E37:E90) -> 16 | N35: =COUNTIF(F37:F90,"Completado") -> 0 | O35: =IFERROR(COUNTIF(F37:F90,"Completado")/COUNTA(E37:E90),0) -> 0
B36: ☑ | C36: ✓ | D36: ↳ Epic | E36: Subtarea | F36: Status | G36: Responsable | H36: Fecha Límite | I36: Comentarios
C37: =FALSE() -> FALSE | D37: E6-005 | E37: Definir KPIs del ciclo con el cliente | F37: =IF(C37,"Completado","Pendiente") -> Pendiente
C38: =FALSE() -> FALSE | D38: E6-005 | E38: Configurar cálculo automático de métricas | F38: =IF(C38,"Completado","Pendiente") -> Pendiente
C39: =FALSE() -> FALSE | D39: E6-005 | E39: Configurar reporte periódico automatizado | F39: =IF(C39,"Completado","Pendiente") -> Pendiente
C40: =FALSE() -> FALSE | D40: E6-005 | E40: Validar con gerencia de facturación | F40: =IF(C40,"Completado","Pendiente") -> Pendiente
C42: =FALSE() -> FALSE | D42: E6-006 | E42: Retención documental y cumplimiento normativo | F42: Gestión de retención según normativa vigente con pistas de auditoría inmutables | G42: ECM | H42: MEDIA | I42: =IF(C42,"Completado","Pendiente") -> Pendiente | M42: =COUNTA(E44:E97) -> 10 | N42: =COUNTIF(F44:F97,"Completado") -> 0 | O42: =IFERROR(COUNTIF(F44:F97,"Completado")/COUNTA(E44:E97),0) -> 0
B43: ☑ | C43: ✓ | D43: ↳ Epic | E43: Subtarea | F43: Status | G43: Responsable | H43: Fecha Límite | I43: Comentarios
C44: =FALSE() -> FALSE | D44: E6-006 | E44: Mapear normativa de retención por país (CO/MX/PE) | F44: =IF(C44,"Completado","Pendiente") -> Pendiente
C45: =FALSE() -> FALSE | D45: E6-006 | E45: Configurar políticas de retención en ECM | F45: =IF(C45,"Completado","Pendiente") -> Pendiente
C46: =FALSE() -> FALSE | D46: E6-006 | E46: Configurar pistas de auditoría inmutables | F46: =IF(C46,"Completado","Pendiente") -> Pendiente
C47: =FALSE() -> FALSE | D47: E6-006 | E47: Pruebas de cumplimiento normativo | F47: =IF(C47,"Completado","Pendiente") -> Pendiente
...

Sheet 📋 Instrucciones
A2: HYLAND | Instrucciones de Uso del Epic Tracker
A4: Estructura del archivo
B5: 📊 Dashboard | C5: Vista consolidada: KPIs globales + tabla de progreso por etapa. Las fórmulas se actualizan automáticamente al cambiar status o agregar/eliminar subtareas.
B6: E1 – E6 | C6: Una hoja por etapa. Cada etapa contiene sus Epics (funcionalidades) y las Subtareas que deben completarse para considerar el Epic terminado.
A8: Cómo usar el checkbox
B9: Marcar como completada | C9: Haga clic en el checkbox ☑ en la columna B. Esto activa la celda oculta en col C (TRUE) y la fórmula de Status cambia automáticamente a 'Completado'.
B10: Desmarcar | C10: Haga clic nuevamente en el checkbox para deseleccionarlo. El Status vuelve a 'Pendiente' automáticamente.
B11: Status manual | C11: El campo Status también acepta valores del menú desplegable (Pendiente, En Progreso, En Revisión, Completado, Bloqueado) para casos donde el checkbox no sea suficiente.
A13: Fórmulas dinámicas de % Avance
B14: Por Epic | C14: Completadas dividido entre COUNTA(nombres de subtareas). Al agregar una subtarea nueva en la zona de buffer, el conteo se actualiza solo.
B15: Por Etapa | C15: Igual que por Epic, pero sobre todo el rango F7:F{last_row} de la hoja.
B16: En Dashboard | C16: Todas las fórmulas del Dashboard referencian los rangos de las hojas de etapa. Se actualizan sin intervención.
B17: Agregar subtareas | C17: Insertar filas dentro del rango de subtareas del Epic (entre la primera y última subtarea existente) para que las fórmulas las incluyan automáticamente.
A19: Campos editables
B20: Status (Epic/Subtarea) | C20: Dropdown: Pendiente / En Progreso / En Revisión / Completado / Bloqueado
B21: Responsable | C21: Nombre o siglas del responsable
B22: Fecha Inicio / Fecha Límite | C22: Formato DD/MM/AAAA
B23: Comentarios | C23: Notas de avance, bloqueantes o decisiones
A25: Leyenda de Status
B26: Pendiente | C26: Identificado, no iniciado
B27: En Progreso | C27: Activamente en desarrollo
B28: En Revisión | C28: En validación con cliente o equipo técnico
B29: Completado | C29: Finalizado y validado
B30: Bloqueado | C30: Detenido por dependencia o problema técnico
A32: Confidencial — Uso interno Hyland | 2025
