Workbook

Sheet 📊 Dashboard
B2: HYLAND — Cuentas Médicas para Prestadores de Servicios
B3: Tracker de Epics · Realineado a la demostración final · Actualizado 2026-07-03
B6: =COUNTA('E1 · Captura'!J7:J500)+COUNTA('E2 · Validación IA'!J7:J500)+COUNTA('E3 · Envío'!J7:J500)+COUNTA('E4 · Glosas'!J7:J500)+COUNTA('E5 · Apelación'!J7:J500)+COUNTA('E6 · Pago y Cierre'!J7:J500) -> 45 | C6: =(COUNTIF('E1 · Captura'!F7:F500,"Pendiente")+COUNTIF('E1 · Captura'!F7:F500,"En Progreso")+COUNTIF('E1 · Captura'!F7:F500,"En Revisión")+COUNTIF('E1 · Captura'!F7:F500,"Completado")+COUNTIF('E1 · Captura'!F7:F500,"Bloqueado"))+(COUNTIF('E2 · Validación IA'!F7:F500,"Pendiente")+COUNTIF('E2 · Validación IA'!F7:F500,"En Progreso")+COUNTIF('E2 · Validación IA'!F7:F500,"En Revisión")+COUNTIF('E2 · Validación IA'!F7:F500,"Completado")+COUNTIF('E2 · Validación IA'!F7:F500,"Bloqueado"))+(COUNTIF('E3 · Envío'!F7:F500,"Pendiente")+COUNTIF('E3 · Envío'!F7:F500,"En Progreso")+COUNTIF('E3 · Envío'!F7:F500,"En Revisión")+COUNTIF('E3 · Envío'!F7:F500,"Completado")+COUNTIF('E3 · Envío'!F7:F500,"Bloqueado"))+(COUNTIF('E4 · Glosas'!F7:F500,"Pendiente")+COUNTIF('E4 · Glosas'!F7:F500,"En Progreso")+COUNTIF('E4 · Glosas'!F7:F500,"En Revisión")+COUNTIF('E4 · Glosas'!F7:F500,"Completado")+COUNTIF('E4 · Glosas'!F7:F500,"Bloqueado"))+(COUNTIF('E5 · Apelación'!F7:F500,"Pendiente")+COUNTIF('E5 · Apelación'!F7:F500,"En Progreso")+COUNTIF('E5 · Apelación'!F7:F500,"En Revisión")+COUNTIF('E5 · Apelación'!F7:F500,"Completado")+COUNTIF('E5 · Apelación'!F7:F500,"Bloqueado"))+(COUNTIF('E6 · Pago y Cierre'!F7:F500,"Pendiente")+COUNTIF('E6 · Pago y Cierre'!F7:F500,"En Progreso")+COUNTIF('E6 · Pago y Cierre'!F7:F500,"En Revisión")+COUNTIF('E6 · Pago y Cierre'!F7:F500,"Completado")+COUNTIF('E6 · Pago y Cierre'!F7:F500,"Bloqueado")) -> 187 | D6: =COUNTIF('E1 · Captura'!F7:F500,"Completado")+COUNTIF('E2 · Validación IA'!F7:F500,"Completado")+COUNTIF('E3 · Envío'!F7:F500,"Completado")+COUNTIF('E4 · Glosas'!F7:F500,"Completado")+COUNTIF('E5 · Apelación'!F7:F500,"Completado")+COUNTIF('E6 · Pago y Cierre'!F7:F500,"Completado") -> 29 | E6: =COUNTIF('E1 · Captura'!F7:F500,"En Progreso")+COUNTIF('E2 · Validación IA'!F7:F500,"En Progreso")+COUNTIF('E3 · Envío'!F7:F500,"En Progreso")+COUNTIF('E4 · Glosas'!F7:F500,"En Progreso")+COUNTIF('E5 · Apelación'!F7:F500,"En Progreso")+COUNTIF('E6 · Pago y Cierre'!F7:F500,"En Progreso") -> 26 | F6: =COUNTIF('E1 · Captura'!F7:F500,"Pendiente")+COUNTIF('E2 · Validación IA'!F7:F500,"Pendiente")+COUNTIF('E3 · Envío'!F7:F500,"Pendiente")+COUNTIF('E4 · Glosas'!F7:F500,"Pendiente")+COUNTIF('E5 · Apelación'!F7:F500,"Pendiente")+COUNTIF('E6 · Pago y Cierre'!F7:F500,"Pendiente") -> 132 | G6: =COUNTIF('E1 · Captura'!F7:F500,"Bloqueado")+COUNTIF('E2 · Validación IA'!F7:F500,"Bloqueado")+COUNTIF('E3 · Envío'!F7:F500,"Bloqueado")+COUNTIF('E4 · Glosas'!F7:F500,"Bloqueado")+COUNTIF('E5 · Apelación'!F7:F500,"Bloqueado")+COUNTIF('E6 · Pago y Cierre'!F7:F500,"Bloqueado") -> 0
B7: Epics | C7: Subtareas | D7: Completadas | E7: En Progreso | F7: Pendientes | G7: Bloqueadas
B9: Etapa | C9: Epics | D9: Subtareas | E9: Completadas | F9: En Progreso | G9: Pendientes | H9: Bloqueadas | I9: % Avance
B10: E1 — Captura y Estructuración del Evento Clínico | C10: =COUNTA('E1 · Captura'!J7:J500) -> 11 | D10: =(COUNTIF('E1 · Captura'!F7:F500,"Pendiente")+COUNTIF('E1 · Captura'!F7:F500,"En Progreso")+COUNTIF('E1 · Captura'!F7:F500,"En Revisión")+COUNTIF('E1 · Captura'!F7:F500,"Completado")+COUNTIF('E1 · Captura'!F7:F500,"Bloqueado")) -> 51 | E10: =COUNTIF('E1 · Captura'!F7:F500,"Completado") -> 15 | F10: =COUNTIF('E1 · Captura'!F7:F500,"En Progreso") -> 18 | G10: =COUNTIF('E1 · Captura'!F7:F500,"Pendiente") -> 18 | H10: =COUNTIF('E1 · Captura'!F7:F500,"Bloqueado") -> 0 | I10: =IFERROR(E10/D10,0) -> 0.29411765
B11: E2 — Validación Previa con Agente IA | C11: =COUNTA('E2 · Validación IA'!J7:J500) -> 7 | D11: =(COUNTIF('E2 · Validación IA'!F7:F500,"Pendiente")+COUNTIF('E2 · Validación IA'!F7:F500,"En Progreso")+COUNTIF('E2 · Validación IA'!F7:F500,"En Revisión")+COUNTIF('E2 · Validación IA'!F7:F500,"Completado")+COUNTIF('E2 · Validación IA'!F7:F500,"Bloqueado")) -> 33 | E11: =COUNTIF('E2 · Validación IA'!F7:F500,"Completado") -> 14 | F11: =COUNTIF('E2 · Validación IA'!F7:F500,"En Progreso") -> 8 | G11: =COUNTIF('E2 · Validación IA'!F7:F500,"Pendiente") -> 11 | H11: =COUNTIF('E2 · Validación IA'!F7:F500,"Bloqueado") -> 0 | I11: =IFERROR(E11/D11,0) -> 0.42424242
B12: E3 — Armado y Envío de la Cuenta | C12: =COUNTA('E3 · Envío'!J7:J500) -> 6 | D12: =(COUNTIF('E3 · Envío'!F7:F500,"Pendiente")+COUNTIF('E3 · Envío'!F7:F500,"En Progreso")+COUNTIF('E3 · Envío'!F7:F500,"En Revisión")+COUNTIF('E3 · Envío'!F7:F500,"Completado")+COUNTIF('E3 · Envío'!F7:F500,"Bloqueado")) -> 24 | E12: =COUNTIF('E3 · Envío'!F7:F500,"Completado") -> 0 | F12: =COUNTIF('E3 · Envío'!F7:F500,"En Progreso") -> 0 | G12: =COUNTIF('E3 · Envío'!F7:F500,"Pendiente") -> 24 | H12: =COUNTIF('E3 · Envío'!F7:F500,"Bloqueado") -> 0 | I12: =IFERROR(E12/D12,0) -> 0
B13: E4 — Recepción y Gestión de Glosas | C13: =COUNTA('E4 · Glosas'!J7:J500) -> 8 | D13: =(COUNTIF('E4 · Glosas'!F7:F500,"Pendiente")+COUNTIF('E4 · Glosas'!F7:F500,"En Progreso")+COUNTIF('E4 · Glosas'!F7:F500,"En Revisión")+COUNTIF('E4 · Glosas'!F7:F500,"Completado")+COUNTIF('E4 · Glosas'!F7:F500,"Bloqueado")) -> 30 | E13: =COUNTIF('E4 · Glosas'!F7:F500,"Completado") -> 0 | F13: =COUNTIF('E4 · Glosas'!F7:F500,"En Progreso") -> 0 | G13: =COUNTIF('E4 · Glosas'!F7:F500,"Pendiente") -> 30 | H13: =COUNTIF('E4 · Glosas'!F7:F500,"Bloqueado") -> 0 | I13: =IFERROR(E13/D13,0) -> 0
B14: E5 — Respuesta y Apelación de Glosas | C14: =COUNTA('E5 · Apelación'!J7:J500) -> 6 | D14: =(COUNTIF('E5 · Apelación'!F7:F500,"Pendiente")+COUNTIF('E5 · Apelación'!F7:F500,"En Progreso")+COUNTIF('E5 · Apelación'!F7:F500,"En Revisión")+COUNTIF('E5 · Apelación'!F7:F500,"Completado")+COUNTIF('E5 · Apelación'!F7:F500,"Bloqueado")) -> 22 | E14: =COUNTIF('E5 · Apelación'!F7:F500,"Completado") -> 0 | F14: =COUNTIF('E5 · Apelación'!F7:F500,"En Progreso") -> 0 | G14: =COUNTIF('E5 · Apelación'!F7:F500,"Pendiente") -> 22 | H14: =COUNTIF('E5 · Apelación'!F7:F500,"Bloqueado") -> 0 | I14: =IFERROR(E14/D14,0) -> 0
B15: E6 — Seguimiento de Pago, Conciliación y Cierre | C15: =COUNTA('E6 · Pago y Cierre'!J7:J500) -> 7 | D15: =(COUNTIF('E6 · Pago y Cierre'!F7:F500,"Pendiente")+COUNTIF('E6 · Pago y Cierre'!F7:F500,"En Progreso")+COUNTIF('E6 · Pago y Cierre'!F7:F500,"En Revisión")+COUNTIF('E6 · Pago y Cierre'!F7:F500,"Completado")+COUNTIF('E6 · Pago y Cierre'!F7:F500,"Bloqueado")) -> 27 | E15: =COUNTIF('E6 · Pago y Cierre'!F7:F500,"Completado") -> 0 | F15: =COUNTIF('E6 · Pago y Cierre'!F7:F500,"En Progreso") -> 0 | G15: =COUNTIF('E6 · Pago y Cierre'!F7:F500,"Pendiente") -> 27 | H15: =COUNTIF('E6 · Pago y Cierre'!F7:F500,"Bloqueado") -> 0 | I15: =IFERROR(E15/D15,0) -> 0
B16: TOTAL GENERAL | C16: =SUM(C10:C15) -> 45 | D16: =SUM(D10:D15) -> 187 | E16: =SUM(E10:E15) -> 29 | F16: =SUM(F10:F15) -> 26 | G16: =SUM(G10:G15) -> 132 | H16: =SUM(H10:H15) -> 0 | I16: =IFERROR(E16/D16,0) -> 0.15508021
B18: Avance por Fase
B19: Fase | C19: Epics | D19: Subtareas | E19: Completadas | F19: En Progreso | G19: Pendientes | H19: % Avance
B20: Demo | C20: =COUNTIF('E1 · Captura'!J7:J500,"Demo")+COUNTIF('E2 · Validación IA'!J7:J500,"Demo")+COUNTIF('E3 · Envío'!J7:J500,"Demo")+COUNTIF('E4 · Glosas'!J7:J500,"Demo")+COUNTIF('E5 · Apelación'!J7:J500,"Demo")+COUNTIF('E6 · Pago y Cierre'!J7:J500,"Demo") -> 14 | D20: =SUMIF('E1 · Captura'!J7:J500,"Demo",'E1 · Captura'!N7:N500)+SUMIF('E2 · Validación IA'!J7:J500,"Demo",'E2 · Validación IA'!N7:N500)+SUMIF('E3 · Envío'!J7:J500,"Demo",'E3 · Envío'!N7:N500)+SUMIF('E4 · Glosas'!J7:J500,"Demo",'E4 · Glosas'!N7:N500)+SUMIF('E5 · Apelación'!J7:J500,"Demo",'E5 · Apelación'!N7:N500)+SUMIF('E6 · Pago y Cierre'!J7:J500,"Demo",'E6 · Pago y Cierre'!N7:N500) -> 68 | E20: =SUMIF('E1 · Captura'!J7:J500,"Demo",'E1 · Captura'!O7:O500)+SUMIF('E2 · Validación IA'!J7:J500,"Demo",'E2 · Validación IA'!O7:O500)+SUMIF('E3 · Envío'!J7:J500,"Demo",'E3 · Envío'!O7:O500)+SUMIF('E4 · Glosas'!J7:J500,"Demo",'E4 · Glosas'!O7:O500)+SUMIF('E5 · Apelación'!J7:J500,"Demo",'E5 · Apelación'!O7:O500)+SUMIF('E6 · Pago y Cierre'!J7:J500,"Demo",'E6 · Pago y Cierre'!O7:O500) -> 28 | F20: =SUMIF('E1 · Captura'!J7:J500,"Demo",'E1 · Captura'!R7:R500)+SUMIF('E2 · Validación IA'!J7:J500,"Demo",'E2 · Validación IA'!R7:R500)+SUMIF('E3 · Envío'!J7:J500,"Demo",'E3 · Envío'!R7:R500)+SUMIF('E4 · Glosas'!J7:J500,"Demo",'E4 · Glosas'!R7:R500)+SUMIF('E5 · Apelación'!J7:J500,"Demo",'E5 · Apelación'!R7:R500)+SUMIF('E6 · Pago y Cierre'!J7:J500,"Demo",'E6 · Pago y Cierre'!R7:R500) -> 26 | G20: =SUMIF('E1 · Captura'!J7:J500,"Demo",'E1 · Captura'!S7:S500)+SUMIF('E2 · Validación IA'!J7:J500,"Demo",'E2 · Validación IA'!S7:S500)+SUMIF('E3 · Envío'!J7:J500,"Demo",'E3 · Envío'!S7:S500)+SUMIF('E4 · Glosas'!J7:J500,"Demo",'E4 · Glosas'!S7:S500)+SUMIF('E5 · Apelación'!J7:J500,"Demo",'E5 · Apelación'!S7:S500)+SUMIF('E6 · Pago y Cierre'!J7:J500,"Demo",'E6 · Pago y Cierre'!S7:S500) -> 14 | H20: =IFERROR(E20/D20,0) -> 0.41176471
B21: Fase 2 | C21: =COUNTIF('E1 · Captura'!J7:J500,"Fase 2")+COUNTIF('E2 · Validación IA'!J7:J500,"Fase 2")+COUNTIF('E3 · Envío'!J7:J500,"Fase 2")+COUNTIF('E4 · Glosas'!J7:J500,"Fase 2")+COUNTIF('E5 · Apelación'!J7:J500,"Fase 2")+COUNTIF('E6 · Pago y Cierre'!J7:J500,"Fase 2") -> 17 | D21: =SUMIF('E1 · Captura'!J7:J500,"Fase 2",'E1 · Captura'!N7:N500)+SUMIF('E2 · Validación IA'!J7:J500,"Fase 2",'E2 · Validación IA'!N7:N500)+SUMIF('E3 · Envío'!J7:J500,"Fase 2",'E3 · Envío'!N7:N500)+SUMIF('E4 · Glosas'!J7:J500,"Fase 2",'E4 · Glosas'!N7:N500)+SUMIF('E5 · Apelación'!J7:J500,"Fase 2",'E5 · Apelación'!N7:N500)+SUMIF('E6 · Pago y Cierre'!J7:J500,"Fase 2",'E6 · Pago y Cierre'!N7:N500) -> 66 | E21: =SUMIF('E1 · Captura'!J7:J500,"Fase 2",'E1 · Captura'!O7:O500)+SUMIF('E2 · Validación IA'!J7:J500,"Fase 2",'E2 · Validación IA'!O7:O500)+SUMIF('E3 · Envío'!J7:J500,"Fase 2",'E3 · Envío'!O7:O500)+SUMIF('E4 · Glosas'!J7:J500,"Fase 2",'E4 · Glosas'!O7:O500)+SUMIF('E5 · Apelación'!J7:J500,"Fase 2",'E5 · Apelación'!O7:O500)+SUMIF('E6 · Pago y Cierre'!J7:J500,"Fase 2",'E6 · Pago y Cierre'!O7:O500) -> 1 | F21: =SUMIF('E1 · Captura'!J7:J500,"Fase 2",'E1 · Captura'!R7:R500)+SUMIF('E2 · Validación IA'!J7:J500,"Fase 2",'E2 · Validación IA'!R7:R500)+SUMIF('E3 · Envío'!J7:J500,"Fase 2",'E3 · Envío'!R7:R500)+SUMIF('E4 · Glosas'!J7:J500,"Fase 2",'E4 · Glosas'!R7:R500)+SUMIF('E5 · Apelación'!J7:J500,"Fase 2",'E5 · Apelación'!R7:R500)+SUMIF('E6 · Pago y Cierre'!J7:J500,"Fase 2",'E6 · Pago y Cierre'!R7:R500) -> 0 | G21: =SUMIF('E1 · Captura'!J7:J500,"Fase 2",'E1 · Captura'!S7:S500)+SUMIF('E2 · Validación IA'!J7:J500,"Fase 2",'E2 · Validación IA'!S7:S500)+SUMIF('E3 · Envío'!J7:J500,"Fase 2",'E3 · Envío'!S7:S500)+SUMIF('E4 · Glosas'!J7:J500,"Fase 2",'E4 · Glosas'!S7:S500)+SUMIF('E5 · Apelación'!J7:J500,"Fase 2",'E5 · Apelación'!S7:S500)+SUMIF('E6 · Pago y Cierre'!J7:J500,"Fase 2",'E6 · Pago y Cierre'!S7:S500) -> 65 | H21: =IFERROR(E21/D21,0) -> 0.015151515
B22: Fase 3 | C22: =COUNTIF('E1 · Captura'!J7:J500,"Fase 3")+COUNTIF('E2 · Validación IA'!J7:J500,"Fase 3")+COUNTIF('E3 · Envío'!J7:J500,"Fase 3")+COUNTIF('E4 · Glosas'!J7:J500,"Fase 3")+COUNTIF('E5 · Apelación'!J7:J500,"Fase 3")+COUNTIF('E6 · Pago y Cierre'!J7:J500,"Fase 3") -> 14 | D22: =SUMIF('E1 · Captura'!J7:J500,"Fase 3",'E1 · Captura'!N7:N500)+SUMIF('E2 · Validación IA'!J7:J500,"Fase 3",'E2 · Validación IA'!N7:N500)+SUMIF('E3 · Envío'!J7:J500,"Fase 3",'E3 · Envío'!N7:N500)+SUMIF('E4 · Glosas'!J7:J500,"Fase 3",'E4 · Glosas'!N7:N500)+SUMIF('E5 · Apelación'!J7:J500,"Fase 3",'E5 · Apelación'!N7:N500)+SUMIF('E6 · Pago y Cierre'!J7:J500,"Fase 3",'E6 · Pago y Cierre'!N7:N500) -> 53 | E22: =SUMIF('E1 · Captura'!J7:J500,"Fase 3",'E1 · Captura'!O7:O500)+SUMIF('E2 · Validación IA'!J7:J500,"Fase 3",'E2 · Validación IA'!O7:O500)+SUMIF('E3 · Envío'!J7:J500,"Fase 3",'E3 · Envío'!O7:O500)+SUMIF('E4 · Glosas'!J7:J500,"Fase 3",'E4 · Glosas'!O7:O500)+SUMIF('E5 · Apelación'!J7:J500,"Fase 3",'E5 · Apelación'!O7:O500)+SUMIF('E6 · Pago y Cierre'!J7:J500,"Fase 3",'E6 · Pago y Cierre'!O7:O500) -> 0 | F22: =SUMIF('E1 · Captura'!J7:J500,"Fase 3",'E1 · Captura'!R7:R500)+SUMIF('E2 · Validación IA'!J7:J500,"Fase 3",'E2 · Validación IA'!R7:R500)+SUMIF('E3 · Envío'!J7:J500,"Fase 3",'E3 · Envío'!R7:R500)+SUMIF('E4 · Glosas'!J7:J500,"Fase 3",'E4 · Glosas'!R7:R500)+SUMIF('E5 · Apelación'!J7:J500,"Fase 3",'E5 · Apelación'!R7:R500)+SUMIF('E6 · Pago y Cierre'!J7:J500,"Fase 3",'E6 · Pago y Cierre'!R7:R500) -> 0 | G22: =SUMIF('E1 · Captura'!J7:J500,"Fase 3",'E1 · Captura'!S7:S500)+SUMIF('E2 · Validación IA'!J7:J500,"Fase 3",'E2 · Validación IA'!S7:S500)+SUMIF('E3 · Envío'!J7:J500,"Fase 3",'E3 · Envío'!S7:S500)+SUMIF('E4 · Glosas'!J7:J500,"Fase 3",'E4 · Glosas'!S7:S500)+SUMIF('E5 · Apelación'!J7:J500,"Fase 3",'E5 · Apelación'!S7:S500)+SUMIF('E6 · Pago y Cierre'!J7:J500,"Fase 3",'E6 · Pago y Cierre'!S7:S500) -> 53 | H22: =IFERROR(E22/D22,0) -> 0
B24: =CONCATENATE("▶ Avance de la fase DEMO: ",TEXT(H20,"0%")," — ",E20," de ",D20," subtareas completadas (",F20," en progreso, ",G20," pendientes)") -> ▶ Avance de la fase DEMO: 41% — 28 de 68 subtareas completadas (26 en progreso, 14 pendientes)

Sheet E1 · Captura
A2: HYLAND | Cuentas Médicas — Prestadores de Servicios
A3: Etapa 1 — Captura y Estructuración del Evento Clínico
A4: El proceso inicia con la atención al paciente. Se consolidan documentos heterogéneos en un expediente digital estructurado. Incluye la base de la demo: IDP, plugin/overview, intake y el reporting dashboard.
B6: ☑ | D6: Epic ID | E6: Nombre del Epic | F6: Descripción | G6: Módulo Hyland | H6: Prioridad | I6: Status | J6: Fase | K6: Responsable | L6: Fecha Inicio | M6: Fecha Límite | N6: Subt. | O6: Compl. | P6: % Avance | Q6: Comentarios / Bloqueantes
D7: E1-001 | E7: Captura multicanal de documentos | F7: Ingesta de documentos desde múltiples canales. En la demo el proceso inicia cargando un documento; los demás conectores quedan para fases posteriores. | G7: IDP | H7: CRÍTICA | I7: En Progreso | J7: Demo | K7: Fernando / Mau | N7: =COUNTIF(F9:F15,"Pendiente")+COUNTIF(F9:F15,"En Progreso")+COUNTIF(F9:F15,"En Revisión")+COUNTIF(F9:F15,"Completado")+COUNTIF(F9:F15,"Bloqueado") -> 7 | O7: =COUNTIF(F9:F15,"Completado") -> 2 | P7: =IFERROR(O7/N7,0) -> 0.28571429 | Q7: Etapa 0 del spec: upload operativo. Conectores adicionales post-demo. | R7: =COUNTIF(F9:F15,"En Progreso") -> 2 | S7: =COUNTIF(F9:F15,"Pendiente") -> 3
D8: ↳ Epic | E8: Subtarea | F8: Status | G8: Responsable | H8: Fecha Límite | I8: Comentarios
D9: E1-001 | E9: Configurar upload para iniciar proceso en Automate | F9: Completado | G9: Fernando | I9: Interfaz Custom UI; el documento inicia el proceso y alimenta IDP
D10: E1-001 | E10: Integración de códigos CUPS (JSON simulado / API) | F10: Completado | G10: Mauricio | I10: Fase 1: JSON simula API. Trigger vía Postman en fase posterior
D11: E1-001 | E11: Configurar conector de escáner de red | F11: En Progreso | G11: Larissa | I11: Web Scanning pendiente; posible video en demo — fase posterior
D12: E1-001 | E12: Configurar conector de email (IMAP/SMTP) | F12: En Progreso | G12: Mauricio | I12: Integración Outlook — fase posterior
D13: E1-001 | E13: Pruebas de ingesta multicanal (WhatsApp) | F13: Pendiente | G13: Mauricio | I13: Trigger WhatsApp — fase posterior
D14: E1-001 | E14: Pruebas de ingesta multicanal (SharePoint) | F14: Pendiente | G14: Mauricio | I14: SharePoint si es posible — fase posterior
D15: E1-001 | E15: Configurar integración HIS (HL7/FHIR) | F15: Pendiente | G15: N/A | I15: Fase posterior
D16: E1-002 | E16: Clasificación automática de documentos | F16: IDP identifica el tipo de documento sin configuración manual (spec Etapa 1). Basado en POC ARS Primera. | G16: IDP | H16: CRÍTICA | I16: En Progreso | J16: Demo | K16: Larissa | N16: =COUNTIF(F18:F22,"Pendiente")+COUNTIF(F18:F22,"En Progreso")+COUNTIF(F18:F22,"En Revisión")+COUNTIF(F18:F22,"Completado")+COUNTIF(F18:F22,"Bloqueado") -> 5 | O16: =COUNTIF(F18:F22,"Completado") -> 2 | P16: =IFERROR(O16/N16,0) -> 0.4 | R16: =COUNTIF(F18:F22,"En Progreso") -> 3 | S16: =COUNTIF(F18:F22,"Pendiente") -> 0
D17: ↳ Epic | E17: Subtarea | F17: Status | G17: Responsable | H17: Fecha Límite | I17: Comentarios
D18: E1-002 | E18: Definir taxonomía de tipos de documento para la demo | F18: En Progreso | G18: Larissa | I18: Muestras ARS Primera; falta acotar y recolectar el set final
D19: E1-002 | E19: Entrenar modelo de clasificación IDP | F19: En Progreso | G19: Larissa
D20: E1-002 | E20: Subclasificación de clases heredadas | F20: En Progreso | G20: Larissa
D21: E1-002 | E21: Validar precisión (umbral ≥ 90%) con lote de demo | F21: Completado | G21: Larissa
D22: E1-002 | E22: Configurar reglas de excepción | F22: Completado | G22: Fernando
D23: E1-003 | E23: Extracción de campos clave | F23: Extrae diagnósticos CIE-10, procedimientos CUPS, medicamentos, fechas, valores y tablas (spec Etapa 1). | G23: IDP | H23: CRÍTICA | I23: En Progreso | J23: Demo | K23: Fernando | N23: =COUNTIF(F25:F28,"Pendiente")+COUNTIF(F25:F28,"En Progreso")+COUNTIF(F25:F28,"En Revisión")+COUNTIF(F25:F28,"Completado")+COUNTIF(F25:F28,"Bloqueado") -> 4 | O23: =COUNTIF(F25:F28,"Completado") -> 2 | P23: =IFERROR(O23/N23,0) -> 0.5 | R23: =COUNTIF(F25:F28,"En Progreso") -> 2 | S23: =COUNTIF(F25:F28,"Pendiente") -> 0
D24: ↳ Epic | E24: Subtarea | F24: Status | G24: Responsable | H24: Fecha Límite | I24: Comentarios
D25: E1-003 | E25: Mapear campos requeridos por aseguradora | F25: Completado | G25: Fernando
D26: E1-003 | E26: Configurar extracción de valores y fechas | F26: Completado | G26: Fernando
D27: E1-003 | E27: Configurar extracción de tablas (factura / desglose) | F27: En Progreso | G27: Fernando | I27: Alimenta batchState y Service Explorer
D28: E1-003 | E28: Agrupación documental por cuenta / paciente / factura | F28: En Progreso | G28: Fernando | I28: Prepara batchState para intake
D29: E1-004 | E29: IDP Fase 1 — Documentos de demostración ARS Primera | F29: Set documental y tipologías de la demo basados en ARS Primera. Documentos y tipologías EN VALIDACIÓN. | G29: IDP | H29: CRÍTICA | I29: En Progreso | J29: Demo | K29: Larissa / Fernando | N29: =COUNTIF(F31:F34,"Pendiente")+COUNTIF(F31:F34,"En Progreso")+COUNTIF(F31:F34,"En Revisión")+COUNTIF(F31:F34,"Completado")+COUNTIF(F31:F34,"Bloqueado") -> 4 | O29: =COUNTIF(F31:F34,"Completado") -> 0 | P29: =IFERROR(O29/N29,0) -> 0 | Q29: Estos documentos y tipologías están en validación con el equipo. | R29: =COUNTIF(F31:F34,"En Progreso") -> 3 | S29: =COUNTIF(F31:F34,"Pendiente") -> 1
D30: ↳ Epic | E30: Subtarea | F30: Status | G30: Responsable | H30: Fecha Límite | I30: Comentarios
D31: E1-004 | E31: Recolectar muestras documentales ARS Primera | F31: En Progreso | G31: Larissa | I31: En validación
D32: E1-004 | E32: Validar tipologías: Factura y Desglose, Autorización, Objeciones Auditoría, Patología, Laboratorios | F32: En Progreso | G32: Larissa | I32: En validación
D33: E1-004 | E33: Confirmar campos extraídos por tipología | F33: En Progreso | G33: Fernando
D34: E1-004 | E34: Aprobar set final de documentos para la demo | F34: Pendiente | G34: Larissa
D35: E1-005 | E35: Creación del expediente / estado del lote (batchState) | F35: batchState consolida documentos y servicios del evento y alimenta el intake (spec Etapa 1). Falta estructura interna de carpetas por paciente. | G35: ECM / CIC | H35: CRÍTICA | I35: En Progreso | J35: Demo | K35: Fernando | N35: =COUNTIF(F37:F41,"Pendiente")+COUNTIF(F37:F41,"En Progreso")+COUNTIF(F37:F41,"En Revisión")+COUNTIF(F37:F41,"Completado")+COUNTIF(F37:F41,"Bloqueado") -> 5 | O35: =COUNTIF(F37:F41,"Completado") -> 1 | P35: =IFERROR(O35/N35,0) -> 0.2 | R35: =COUNTIF(F37:F41,"En Progreso") -> 0 | S35: =COUNTIF(F37:F41,"Pendiente") -> 4
D36: ↳ Epic | E36: Subtarea | F36: Status | G36: Responsable | H36: Fecha Límite | I36: Comentarios
D37: E1-005 | E37: Construir batchState (objeto / JSON) para intake | F37: Completado | G37: Fernando | I37: Entrada principal de intake-account-widget
D38: E1-005 | E38: Diseñar modelo de objeto del expediente en CIC | F38: Pendiente | I38: Estructura de carpetas por paciente pendiente
D39: E1-005 | E39: Vinculación automática por ID de paciente | F39: Pendiente
D40: E1-005 | E40: Definir Content Types / Schemas y reglas de agrupación | F40: Pendiente
D41: E1-005 | E41: Validación de acceso por roles | F41: Pendiente
D42: E1-006 | E42: Plugin medical-records — Overview / Shell operacional | F42: Punto de entrada: overview de Cuentas Médicas dentro del shell nativo; redirige a las tareas activas de Automate. No es la fuente de verdad de las etapas. | G42: Custom UI (Angular/Nx) | H42: CRÍTICA | I42: En Progreso | J42: Demo | K42: Fernando | N42: =COUNTIF(F44:F47,"Pendiente")+COUNTIF(F44:F47,"En Progreso")+COUNTIF(F44:F47,"En Revisión")+COUNTIF(F44:F47,"Completado")+COUNTIF(F44:F47,"Bloqueado") -> 4 | O42: =COUNTIF(F44:F47,"Completado") -> 1 | P42: =IFERROR(O42/N42,0) -> 0.25 | R42: =COUNTIF(F44:F47,"En Progreso") -> 2 | S42: =COUNTIF(F44:F47,"Pendiente") -> 1
...

Sheet E2 · Validación IA
A2: HYLAND | Cuentas Médicas — Prestadores de Servicios
A3: Etapa 2 — Validación Previa con Agente IA
A4: Antes de enviar la cuenta, la malla agéntica (Coding Integrity, Compliance Alert, Financial Variance sobre Claude Haiku) analiza el expediente; el script consolida los resultados y la consola de Análisis los presenta como consola de decisión.
B6: ☑ | D6: Epic ID | E6: Nombre del Epic | F6: Descripción | G6: Módulo Hyland | H6: Prioridad | I6: Status | J6: Fase | K6: Responsable | L6: Fecha Inicio | M6: Fecha Límite | N6: Subt. | O6: Compl. | P6: % Avance | Q6: Comentarios / Bloqueantes
D7: E2-001 | E7: Agente Coding Integrity | F7: Valida consistencia procedimiento-diagnóstico-código, detecta duplicados y soporte diagnóstico faltante. Outcome codingIntegrityResult. | G7: Agent Builder (Claude Haiku) | H7: CRÍTICA | I7: En Progreso | J7: Demo | K7: Fernando | N7: =COUNTIF(F9:F13,"Pendiente")+COUNTIF(F9:F13,"En Progreso")+COUNTIF(F9:F13,"En Revisión")+COUNTIF(F9:F13,"Completado")+COUNTIF(F9:F13,"Bloqueado") -> 5 | O7: =COUNTIF(F9:F13,"Completado") -> 2 | P7: =IFERROR(O7/N7,0) -> 0.4 | Q7: Key coding-integrity-age-tkfvy. Errores parciales de Agent Builder. | R7: =COUNTIF(F9:F13,"En Progreso") -> 3 | S7: =COUNTIF(F9:F13,"Pendiente") -> 0
D8: ↳ Epic | E8: Subtarea | F8: Status | G8: Responsable | H8: Fecha Límite | I8: Comentarios
D9: E2-001 | E9: Configurar Agent Builder (coding-integrity-age-tkfvy) | F9: Completado | G9: Fernando | I9: Inputs: batchState, codingRules, payerCodingPolicy
D10: E2-001 | E10: Mapear reglas de codificación (codingRules / payerCodingPolicy) | F10: Completado | G10: Fernando
D11: E2-001 | E11: Marcar outcome codingIntegrityResult como Required | F11: En Progreso | G11: Fernando | I11: Si no, Automate avanza con tools o valor vacío
D12: E2-001 | E12: Validar findings / recommendedActions / overallRiskLevel | F12: En Progreso | G12: Fernando
D13: E2-001 | E13: Prueba manual: outcome trae JSON no vacío (event log) | F13: En Progreso | G13: Fernando
D14: E2-002 | E14: Agente Compliance Alert | F14: Valida completitud documental, autorizaciones y soportes; detecta documentos faltantes y servicios bloqueados. Outcome complianceAlertResult. | G14: Agent Builder (Claude Haiku) | H14: CRÍTICA | I14: En Progreso | J14: Demo | K14: Fernando | N14: =COUNTIF(F16:F20,"Pendiente")+COUNTIF(F16:F20,"En Progreso")+COUNTIF(F16:F20,"En Revisión")+COUNTIF(F16:F20,"Completado")+COUNTIF(F16:F20,"Bloqueado") -> 5 | O14: =COUNTIF(F16:F20,"Completado") -> 2 | P14: =IFERROR(O14/N14,0) -> 0.4 | Q14: Key compliance-alert-age-4x5t2. | R14: =COUNTIF(F16:F20,"En Progreso") -> 2 | S14: =COUNTIF(F16:F20,"Pendiente") -> 1
D15: ↳ Epic | E15: Subtarea | F15: Status | G15: Responsable | H15: Fecha Límite | I15: Comentarios
D16: E2-002 | E16: Configurar Agent Builder (compliance-alert-age-4x5t2) | F16: Completado | G16: Fernando | I16: Inputs: batchState, payerCompliancePolicy
D17: E2-002 | E17: Configurar detección de missingDocuments | F17: Completado | G17: Fernando | I17: Se presenta en Custom UI
D18: E2-002 | E18: Marcar outcome complianceAlertResult como Required | F18: En Progreso | G18: Fernando
D19: E2-002 | E19: Validar autorizaciones y servicios bloqueados | F19: En Progreso | G19: Fernando
D20: E2-002 | E20: Integrar Knowledge Discovery para documentos exigidos | F20: Pendiente | I20: Fase posterior: KD no integrado aún
D21: E2-003 | E21: Agente Financial Variance | F21: Compara valores facturados contra tarifas esperadas, revisa montos autorizados y calcula variancias. Outcome financialVarianceResult. | G21: Agent Builder (Claude Haiku) | H21: CRÍTICA | I21: En Progreso | J21: Demo | K21: Fernando | N21: =COUNTIF(F23:F27,"Pendiente")+COUNTIF(F23:F27,"En Progreso")+COUNTIF(F23:F27,"En Revisión")+COUNTIF(F23:F27,"Completado")+COUNTIF(F23:F27,"Bloqueado") -> 5 | O21: =COUNTIF(F23:F27,"Completado") -> 3 | P21: =IFERROR(O21/N21,0) -> 0.6 | Q21: Key finantial-v3-znvmy. | R21: =COUNTIF(F23:F27,"En Progreso") -> 1 | S21: =COUNTIF(F23:F27,"Pendiente") -> 1
D22: ↳ Epic | E22: Subtarea | F22: Status | G22: Responsable | H22: Fecha Límite | I22: Comentarios
D23: E2-003 | E23: Configurar Agent Builder (finantial-v3-znvmy) | F23: Completado | G23: Fernando | I23: Inputs: batchState (slim), tariffAgreement
D24: E2-003 | E24: Cargar tarifarios / tariffAgreement | F24: Completado | G24: Fernando
D25: E2-003 | E25: Configurar comparación de montos y tolerancia | F25: Completado | G25: Fernando
D26: E2-003 | E26: Marcar outcome financialVarianceResult como Required | F26: En Progreso | G26: Fernando
D27: E2-003 | E27: Pruebas con cuentas de distintas aseguradoras | F27: Pendiente | I27: Solo se cuenta con la cuenta de ARS Primera
D28: E2-004 | E28: Consolidación de resultados (Script Automate) | F28: BuildIncrementalUnifiedWidgetPayload une los outcomes de agentes en un envelope genérico. Salida unifiedWidgetPayloadText (spec Etapa 5). | G28: Automate (Script) | H28: CRÍTICA | I28: Completado | J28: Demo | K28: Fernando | N28: =COUNTIF(F30:F33,"Pendiente")+COUNTIF(F30:F33,"En Progreso")+COUNTIF(F30:F33,"En Revisión")+COUNTIF(F30:F33,"Completado")+COUNTIF(F30:F33,"Bloqueado") -> 4 | O28: =COUNTIF(F30:F33,"Completado") -> 4 | P28: =IFERROR(O28/N28,0) -> 1 | R28: =COUNTIF(F30:F33,"En Progreso") -> 0 | S28: =COUNTIF(F30:F33,"Pendiente") -> 0
D29: ↳ Epic | E29: Subtarea | F29: Status | G29: Responsable | H29: Fecha Límite | I29: Comentarios
D30: E2-004 | E30: Mapear json1..json3 (agentes) + json4 (batchState) | F30: Completado | G30: Fernando
D31: E2-004 | E31: Generar unifiedWidgetPayload / unifiedWidgetPayloadText | F31: Completado | G31: Fernando
D32: E2-004 | E32: Manejo de errores y warnings (input vacío / inválido) | F32: Completado | G32: Fernando | I32: No borra resultados previos
D33: E2-004 | E33: Parseo profundo de JSON doblemente encodeado | F33: Completado | G33: Fernando
D34: E2-005 | E34: Consola de Análisis (analysis-task-widget) | F34: Tarea Analysis: consola de decisión con score de riesgo de glosa, tarjetas de los 3 agentes, billed items y acciones (spec Etapa 6). Mapea unifiedWidgetPayloadText. | G34: Custom UI | H34: CRÍTICA | I34: En Progreso | J34: Demo | K34: Fernando | N34: =COUNTIF(F36:F41,"Pendiente")+COUNTIF(F36:F41,"En Progreso")+COUNTIF(F36:F41,"En Revisión")+COUNTIF(F36:F41,"Completado")+COUNTIF(F36:F41,"Bloqueado") -> 6 | O34: =COUNTIF(F36:F41,"Completado") -> 3 | P34: =IFERROR(O34/N34,0) -> 0.5 | R34: =COUNTIF(F36:F41,"En Progreso") -> 2 | S34: =COUNTIF(F36:F41,"Pendiente") -> 1
D35: ↳ Epic | E35: Subtarea | F35: Status | G35: Responsable | H35: Fecha Límite | I35: Comentarios
D36: E2-005 | E36: Resolver envelope y tarjetas de los 3 agentes | F36: Completado | G36: Fernando | I36: Key directa / agents / slotName / fallback por tokens
D37: E2-005 | E37: Score de riesgo de glosa y métricas visuales | F37: Completado | G37: Fernando | I37: Inconsistencies, Missing Docs, Tariff Deviations
D38: E2-005 | E38: Tabla de Billed Items (unión por serviceCode / procedureCode) | F38: En Progreso | G38: Fernando
D39: E2-005 | E39: Gating de Approve Proceed | F39: En Progreso | G39: Fernando | I39: Bloquea si falta agente, JSON inválido o requiere revisión manual
D40: E2-005 | E40: Estados Pending / Invalid agent JSON / parciales | F40: Completado | G40: Fernando
D41: E2-005 | E41: Acciones (Update CUPS, Request Authorization, etc.) | F41: Pendiente | G41: Fernando | I41: Fase posterior: visuales, no mutan variables en v1
D42: E2-006 | E42: Flujo de corrección para el equipo de facturación | F42: Convertir los hallazgos en tareas asignables antes de que la cuenta salga. Los widgets aún no mutan variables (v1). | G42: Automate + Case Mgmt | H42: MEDIA | I42: Pendiente | J42: Fase 2 | N42: =COUNTIF(F44:F47,"Pendiente")+COUNTIF(F44:F47,"En Progreso")+COUNTIF(F44:F47,"En Revisión")+COUNTIF(F44:F47,"Completado")+COUNTIF(F44:F47,"Bloqueado") -> 4 | O42: =COUNTIF(F44:F47,"Completado") -> 0 | P42: =IFERROR(O42/N42,0) -> 0 | R42: =COUNTIF(F44:F47,"En Progreso") -> 0 | S42: =COUNTIF(F44:F47,"Pendiente") -> 4
...

Sheet E3 · Envío
A2: HYLAND | Cuentas Médicas — Prestadores de Servicios
A3: Etapa 3 — Armado y Envío de la Cuenta
A4: Post-demo (spec Etapa 7-8): arma el paquete en el formato de cada aseguradora y lo envía de forma trazable. No incluido en la demo actual.
B6: ☑ | D6: Epic ID | E6: Nombre del Epic | F6: Descripción | G6: Módulo Hyland | H6: Prioridad | I6: Status | J6: Fase | K6: Responsable | L6: Fecha Inicio | M6: Fecha Límite | N6: Subt. | O6: Compl. | P6: % Avance | Q6: Comentarios / Bloqueantes
D7: E3-001 | E7: Generación de RIPS automática | F7: Arma el archivo RIPS en el formato requerido a partir del expediente estructurado (spec Etapa 7). | G7: Automate + ECM | H7: CRÍTICA | I7: Pendiente | J7: Fase 2 | N7: =COUNTIF(F9:F12,"Pendiente")+COUNTIF(F9:F12,"En Progreso")+COUNTIF(F9:F12,"En Revisión")+COUNTIF(F9:F12,"Completado")+COUNTIF(F9:F12,"Bloqueado") -> 4 | O7: =COUNTIF(F9:F12,"Completado") -> 0 | P7: =IFERROR(O7/N7,0) -> 0 | Q7: Post-demo (spec) | R7: =COUNTIF(F9:F12,"En Progreso") -> 0 | S7: =COUNTIF(F9:F12,"Pendiente") -> 4
D8: ↳ Epic | E8: Subtarea | F8: Status | G8: Responsable | H8: Fecha Límite | I8: Comentarios
D9: E3-001 | E9: Mapear campos del expediente al estándar RIPS | F9: Pendiente | I9: Post-demo
D10: E3-001 | E10: Configurar generación de archivo RIPS en Automate | F10: Pendiente | I10: Post-demo
D11: E3-001 | E11: Validar RIPS con validador oficial | F11: Pendiente | I11: Post-demo
D12: E3-001 | E12: Pruebas con múltiples tipos de evento | F12: Pendiente | I12: Post-demo
D13: E3-002 | E13: Soporte multi-formato de envío | F13: Adapta el paquete a XML FHIR, EDI, RIPS o formato propietario según el convenio. | G13: Automate | H13: CRÍTICA | I13: Pendiente | J13: Fase 2 | N13: =COUNTIF(F15:F18,"Pendiente")+COUNTIF(F15:F18,"En Progreso")+COUNTIF(F15:F18,"En Revisión")+COUNTIF(F15:F18,"Completado")+COUNTIF(F15:F18,"Bloqueado") -> 4 | O13: =COUNTIF(F15:F18,"Completado") -> 0 | P13: =IFERROR(O13/N13,0) -> 0 | Q13: Post-demo (spec) | R13: =COUNTIF(F15:F18,"En Progreso") -> 0 | S13: =COUNTIF(F15:F18,"Pendiente") -> 4
D14: ↳ Epic | E14: Subtarea | F14: Status | G14: Responsable | H14: Fecha Límite | I14: Comentarios
D15: E3-002 | E15: Catalogar formatos requeridos por cada aseguradora | F15: Pendiente | I15: Post-demo
D16: E3-002 | E16: Configurar transformadores de formato en Automate | F16: Pendiente | I16: Post-demo
D17: E3-002 | E17: Pruebas de generación por formato | F17: Pendiente | I17: Post-demo
D18: E3-002 | E18: Validación con aseguradoras del cliente | F18: Pendiente | I18: Post-demo
D19: E3-003 | E19: Registro de trazabilidad de envío | F19: Guarda fecha, hora, canal, destinatario y número de radicado como evidencia legal. | G19: ECM | H19: CRÍTICA | I19: Pendiente | J19: Fase 2 | N19: =COUNTIF(F21:F24,"Pendiente")+COUNTIF(F21:F24,"En Progreso")+COUNTIF(F21:F24,"En Revisión")+COUNTIF(F21:F24,"Completado")+COUNTIF(F21:F24,"Bloqueado") -> 4 | O19: =COUNTIF(F21:F24,"Completado") -> 0 | P19: =IFERROR(O19/N19,0) -> 0 | Q19: Post-demo (spec) | R19: =COUNTIF(F21:F24,"En Progreso") -> 0 | S19: =COUNTIF(F21:F24,"Pendiente") -> 4
D20: ↳ Epic | E20: Subtarea | F20: Status | G20: Responsable | H20: Fecha Límite | I20: Comentarios
D21: E3-003 | E21: Definir campos de metadatos de trazabilidad | F21: Pendiente | I21: Post-demo
D22: E3-003 | E22: Configurar escritura automática de log en ECM | F22: Pendiente | I22: Post-demo
D23: E3-003 | E23: Validar inmutabilidad del registro | F23: Pendiente | I23: Post-demo
D24: E3-003 | E24: Pruebas de auditoría | F24: Pendiente | I24: Post-demo
D25: E3-004 | E25: Gestión de portales de aseguradoras (RPA) | F25: Automatiza login y subida de documentos a portales web sin API mediante RPA. | G25: Automate (RPA) | H25: MEDIA | I25: Pendiente | J25: Fase 3 | N25: =COUNTIF(F27:F30,"Pendiente")+COUNTIF(F27:F30,"En Progreso")+COUNTIF(F27:F30,"En Revisión")+COUNTIF(F27:F30,"Completado")+COUNTIF(F27:F30,"Bloqueado") -> 4 | O25: =COUNTIF(F27:F30,"Completado") -> 0 | P25: =IFERROR(O25/N25,0) -> 0 | Q25: Post-demo (spec) | R25: =COUNTIF(F27:F30,"En Progreso") -> 0 | S25: =COUNTIF(F27:F30,"Pendiente") -> 4
D26: ↳ Epic | E26: Subtarea | F26: Status | G26: Responsable | H26: Fecha Límite | I26: Comentarios
D27: E3-004 | E27: Inventariar portales de aseguradoras del cliente | F27: Pendiente | I27: Post-demo
D28: E3-004 | E28: Desarrollar bots RPA por portal | F28: Pendiente | I28: Post-demo
D29: E3-004 | E29: Pruebas de estabilidad de bots | F29: Pendiente | I29: Post-demo
D30: E3-004 | E30: Definir mantenimiento ante cambios de interfaz | F30: Pendiente | I30: Post-demo
D31: E3-005 | E31: Panel de seguimiento de envíos | F31: Dashboard con estado de todas las cuentas enviadas. Puede consolidarse con el Reporting Dashboard (E1-009). | G31: ECM / CIC | H31: MEDIA | I31: Pendiente | J31: Fase 2 | N31: =COUNTIF(F33:F36,"Pendiente")+COUNTIF(F33:F36,"En Progreso")+COUNTIF(F33:F36,"En Revisión")+COUNTIF(F33:F36,"Completado")+COUNTIF(F33:F36,"Bloqueado") -> 4 | O31: =COUNTIF(F33:F36,"Completado") -> 0 | P31: =IFERROR(O31/N31,0) -> 0 | Q31: Post-demo (spec) | R31: =COUNTIF(F33:F36,"En Progreso") -> 0 | S31: =COUNTIF(F33:F36,"Pendiente") -> 4
D32: ↳ Epic | E32: Subtarea | F32: Status | G32: Responsable | H32: Fecha Límite | I32: Comentarios
D33: E3-005 | E33: Definir KPIs del panel con el cliente | F33: Pendiente | I33: Post-demo
D34: E3-005 | E34: Configurar vistas en ECM/CIC | F34: Pendiente | I34: Post-demo
D35: E3-005 | E35: Pruebas de actualización en tiempo real | F35: Pendiente | I35: Post-demo
D36: E3-005 | E36: Capacitación al equipo de facturación | F36: Pendiente | I36: Post-demo
D37: E3-006 | E37: Gestión de reenvíos por rechazo técnico | F37: Si la aseguradora rechaza el envío, el sistema corrige y reenvía automáticamente. | G37: Automate | H37: MEDIA | I37: Pendiente | J37: Fase 2 | N37: =COUNTIF(F39:F42,"Pendiente")+COUNTIF(F39:F42,"En Progreso")+COUNTIF(F39:F42,"En Revisión")+COUNTIF(F39:F42,"Completado")+COUNTIF(F39:F42,"Bloqueado") -> 4 | O37: =COUNTIF(F39:F42,"Completado") -> 0 | P37: =IFERROR(O37/N37,0) -> 0 | Q37: Post-demo (spec) | R37: =COUNTIF(F39:F42,"En Progreso") -> 0 | S37: =COUNTIF(F39:F42,"Pendiente") -> 4
D38: ↳ Epic | E38: Subtarea | F38: Status | G38: Responsable | H38: Fecha Límite | I38: Comentarios
D39: E3-006 | E39: Mapear tipos de rechazo técnico por aseguradora | F39: Pendiente | I39: Post-demo
D40: E3-006 | E40: Configurar lógica de autocorrección en Automate | F40: Pendiente | I40: Post-demo
D41: E3-006 | E41: Definir límite de reintentos y escalación | F41: Pendiente | I41: Post-demo
D42: E3-006 | E42: Pruebas de escenarios de rechazo | F42: Pendiente | I42: Post-demo
...

Sheet E4 · Glosas
A2: HYLAND | Cuentas Médicas — Prestadores de Servicios
A3: Etapa 4 — Recepción y Gestión de Glosas
A4: Post-demo (spec Etapa 8): recepción de glosas, apertura de caso e inteligencia histórica para decidir aceptar o apelar. No incluido en la demo actual.
B6: ☑ | D6: Epic ID | E6: Nombre del Epic | F6: Descripción | G6: Módulo Hyland | H6: Prioridad | I6: Status | J6: Fase | K6: Responsable | L6: Fecha Inicio | M6: Fecha Límite | N6: Subt. | O6: Compl. | P6: % Avance | Q6: Comentarios / Bloqueantes
D7: E4-001 | E7: Recepción automática de respuestas de glosa | F7: Captura la respuesta de la aseguradora y la vincula al expediente original (spec Etapa 8). | G7: IDP + Automate | H7: CRÍTICA | I7: Pendiente | J7: Fase 2 | N7: =COUNTIF(F9:F12,"Pendiente")+COUNTIF(F9:F12,"En Progreso")+COUNTIF(F9:F12,"En Revisión")+COUNTIF(F9:F12,"Completado")+COUNTIF(F9:F12,"Bloqueado") -> 4 | O7: =COUNTIF(F9:F12,"Completado") -> 0 | P7: =IFERROR(O7/N7,0) -> 0 | Q7: Post-demo (spec) | R7: =COUNTIF(F9:F12,"En Progreso") -> 0 | S7: =COUNTIF(F9:F12,"Pendiente") -> 4
D8: ↳ Epic | E8: Subtarea | F8: Status | G8: Responsable | H8: Fecha Límite | I8: Comentarios
D9: E4-001 | E9: Configurar captura de glosas por email | F9: Pendiente | I9: Post-demo
D10: E4-001 | E10: Configurar captura de glosas por portal | F10: Pendiente | I10: Post-demo
D11: E4-001 | E11: Configurar captura por EDI | F11: Pendiente | I11: Post-demo
D12: E4-001 | E12: Validar vinculación automática al expediente | F12: Pendiente | I12: Post-demo
D13: E4-002 | E13: Apertura automática de caso de glosa | F13: Cada glosa genera un caso en Case Management asignado al auditor responsable. | G13: Case Management | H13: CRÍTICA | I13: Pendiente | J13: Fase 2 | N13: =COUNTIF(F15:F18,"Pendiente")+COUNTIF(F15:F18,"En Progreso")+COUNTIF(F15:F18,"En Revisión")+COUNTIF(F15:F18,"Completado")+COUNTIF(F15:F18,"Bloqueado") -> 4 | O13: =COUNTIF(F15:F18,"Completado") -> 0 | P13: =IFERROR(O13/N13,0) -> 0 | Q13: Post-demo (spec) | R13: =COUNTIF(F15:F18,"En Progreso") -> 0 | S13: =COUNTIF(F15:F18,"Pendiente") -> 4
D14: ↳ Epic | E14: Subtarea | F14: Status | G14: Responsable | H14: Fecha Límite | I14: Comentarios
D15: E4-002 | E15: Configurar template de caso de glosa | F15: Pendiente | I15: Post-demo
D16: E4-002 | E16: Definir reglas de asignación automática | F16: Pendiente | I16: Post-demo
D17: E4-002 | E17: Configurar notificación al auditor responsable | F17: Pendiente | I17: Post-demo
D18: E4-002 | E18: Pruebas de apertura automática end-to-end | F18: Pendiente | I18: Post-demo
D19: E4-003 | E19: Análisis de recurrencia con Knowledge Discovery | F19: Muestra si la misma glosa se ha recibido antes y cuál fue el resultado al apelar. | G19: Knowledge Discovery | H19: CRÍTICA | I19: Pendiente | J19: Fase 3 | N19: =COUNTIF(F21:F24,"Pendiente")+COUNTIF(F21:F24,"En Progreso")+COUNTIF(F21:F24,"En Revisión")+COUNTIF(F21:F24,"Completado")+COUNTIF(F21:F24,"Bloqueado") -> 4 | O19: =COUNTIF(F21:F24,"Completado") -> 0 | P19: =IFERROR(O19/N19,0) -> 0 | Q19: Post-demo (spec) | R19: =COUNTIF(F21:F24,"En Progreso") -> 0 | S19: =COUNTIF(F21:F24,"Pendiente") -> 4
D20: ↳ Epic | E20: Subtarea | F20: Status | G20: Responsable | H20: Fecha Límite | I20: Comentarios
D21: E4-003 | E21: Configurar indexación de glosas por código y aseguradora | F21: Pendiente | I21: Post-demo
D22: E4-003 | E22: Configurar panel de recurrencia en el caso | F22: Pendiente | I22: Post-demo
D23: E4-003 | E23: Calcular tasa histórica de éxito en apelación | F23: Pendiente | I23: Post-demo
D24: E4-003 | E24: Validar con auditor de referencia del cliente | F24: Pendiente | I24: Post-demo
D25: E4-004 | E25: Dashboard de glosas por aseguradora y código | F25: Visualización agregada de glosas por aseguradora, tipo y valor objetado. | G25: ECM / CIC | H25: MEDIA | I25: Pendiente | J25: Fase 2 | N25: =COUNTIF(F27:F30,"Pendiente")+COUNTIF(F27:F30,"En Progreso")+COUNTIF(F27:F30,"En Revisión")+COUNTIF(F27:F30,"Completado")+COUNTIF(F27:F30,"Bloqueado") -> 4 | O25: =COUNTIF(F27:F30,"Completado") -> 0 | P25: =IFERROR(O25/N25,0) -> 0 | Q25: Post-demo (spec) | R25: =COUNTIF(F27:F30,"En Progreso") -> 0 | S25: =COUNTIF(F27:F30,"Pendiente") -> 4
D26: ↳ Epic | E26: Subtarea | F26: Status | G26: Responsable | H26: Fecha Límite | I26: Comentarios
D27: E4-004 | E27: Definir dimensiones de análisis con el cliente | F27: Pendiente | I27: Post-demo
D28: E4-004 | E28: Configurar dashboard en ECM/CIC | F28: Pendiente | I28: Post-demo
D29: E4-004 | E29: Configurar actualización automática | F29: Pendiente | I29: Post-demo
D30: E4-004 | E30: Capacitación a gerencia de facturación | F30: Pendiente | I30: Post-demo
D31: E4-005 | E31: Alertas de vencimiento de plazo de respuesta | F31: Notificaciones automáticas cuando se acerca el plazo legal para responder. | G31: Automate | H31: CRÍTICA | I31: Pendiente | J31: Fase 2 | N31: =COUNTIF(F33:F36,"Pendiente")+COUNTIF(F33:F36,"En Progreso")+COUNTIF(F33:F36,"En Revisión")+COUNTIF(F33:F36,"Completado")+COUNTIF(F33:F36,"Bloqueado") -> 4 | O31: =COUNTIF(F33:F36,"Completado") -> 0 | P31: =IFERROR(O31/N31,0) -> 0 | Q31: Post-demo (spec) | R31: =COUNTIF(F33:F36,"En Progreso") -> 0 | S31: =COUNTIF(F33:F36,"Pendiente") -> 4
D32: ↳ Epic | E32: Subtarea | F32: Status | G32: Responsable | H32: Fecha Límite | I32: Comentarios
D33: E4-005 | E33: Mapear plazos legales por aseguradora y país | F33: Pendiente | I33: Post-demo
D34: E4-005 | E34: Configurar cálculo de fecha límite en Automate | F34: Pendiente | I34: Post-demo
D35: E4-005 | E35: Configurar alertas T-5, T-2 y T-0 días | F35: Pendiente | I35: Post-demo
D36: E4-005 | E36: Pruebas de escalación ante inacción | F36: Pendiente | I36: Post-demo
D37: E4-006 | E37: Clasificación de glosas por tipo | F37: Categoriza la glosa: técnica, administrativa, documental o de cobertura. | G37: Agente IA + IDP | H37: MEDIA | I37: Pendiente | J37: Fase 2 | N37: =COUNTIF(F39:F41,"Pendiente")+COUNTIF(F39:F41,"En Progreso")+COUNTIF(F39:F41,"En Revisión")+COUNTIF(F39:F41,"Completado")+COUNTIF(F39:F41,"Bloqueado") -> 3 | O37: =COUNTIF(F39:F41,"Completado") -> 0 | P37: =IFERROR(O37/N37,0) -> 0 | Q37: Post-demo (spec) | R37: =COUNTIF(F39:F41,"En Progreso") -> 0 | S37: =COUNTIF(F39:F41,"Pendiente") -> 3
D38: ↳ Epic | E38: Subtarea | F38: Status | G38: Responsable | H38: Fecha Límite | I38: Comentarios
D39: E4-006 | E39: Definir taxonomía de tipos de glosa | F39: Pendiente | I39: Post-demo
D40: E4-006 | E40: Configurar clasificador en el agente IA | F40: Pendiente | I40: Post-demo
D41: E4-006 | E41: Pruebas de precisión de clasificación | F41: Pendiente | I41: Post-demo
D42: E4-007 | E42: Cálculo de impacto financiero en tiempo real | F42: Calcula el monto total objetado, en apelación y la proyección de recupero. | G42: ECM / CIC | H42: MEDIA | I42: Pendiente | J42: Fase 3 | N42: =COUNTIF(F44:F46,"Pendiente")+COUNTIF(F44:F46,"En Progreso")+COUNTIF(F44:F46,"En Revisión")+COUNTIF(F44:F46,"Completado")+COUNTIF(F44:F46,"Bloqueado") -> 3 | O42: =COUNTIF(F44:F46,"Completado") -> 0 | P42: =IFERROR(O42/N42,0) -> 0 | Q42: Post-demo (spec) | R42: =COUNTIF(F44:F46,"En Progreso") -> 0 | S42: =COUNTIF(F44:F46,"Pendiente") -> 3
...

Sheet E5 · Apelación
A2: HYLAND | Cuentas Médicas — Prestadores de Servicios
A3: Etapa 5 — Respuesta y Apelación de Glosas
A4: Post-demo (spec Etapa 8): el Agente IA ayuda a construir el argumento de apelación con soporte documental y precedentes. No incluido en la demo actual.
B6: ☑ | D6: Epic ID | E6: Nombre del Epic | F6: Descripción | G6: Módulo Hyland | H6: Prioridad | I6: Status | J6: Fase | K6: Responsable | L6: Fecha Inicio | M6: Fecha Límite | N6: Subt. | O6: Compl. | P6: % Avance | Q6: Comentarios / Bloqueantes
D7: E5-001 | E7: Asistencia del Agente IA para construir la apelación | F7: El agente identifica documentos, sugiere el argumento y redacta el borrador (spec Etapa 8). | G7: Agente IA + KD | H7: CRÍTICA | I7: Pendiente | J7: Fase 2 | N7: =COUNTIF(F9:F12,"Pendiente")+COUNTIF(F9:F12,"En Progreso")+COUNTIF(F9:F12,"En Revisión")+COUNTIF(F9:F12,"Completado")+COUNTIF(F9:F12,"Bloqueado") -> 4 | O7: =COUNTIF(F9:F12,"Completado") -> 0 | P7: =IFERROR(O7/N7,0) -> 0 | Q7: Post-demo (spec) | R7: =COUNTIF(F9:F12,"En Progreso") -> 0 | S7: =COUNTIF(F9:F12,"Pendiente") -> 4
D8: ↳ Epic | E8: Subtarea | F8: Status | G8: Responsable | H8: Fecha Límite | I8: Comentarios
D9: E5-001 | E9: Configurar recuperación de documentos relevantes del expediente | F9: Pendiente | I9: Post-demo
D10: E5-001 | E10: Configurar generación de borrador de apelación | F10: Pendiente | I10: Post-demo
D11: E5-001 | E11: Integrar precedentes exitosos del KD al borrador | F11: Pendiente | I11: Post-demo
D12: E5-001 | E12: Validación con auditor senior del cliente | F12: Pendiente | I12: Post-demo
D13: E5-002 | E13: Búsqueda de precedentes exitosos | F13: Recupera casos similares donde la apelación fue aceptada y los argumentos que funcionaron. | G13: Knowledge Discovery | H13: CRÍTICA | I13: Pendiente | J13: Fase 3 | N13: =COUNTIF(F15:F18,"Pendiente")+COUNTIF(F15:F18,"En Progreso")+COUNTIF(F15:F18,"En Revisión")+COUNTIF(F15:F18,"Completado")+COUNTIF(F15:F18,"Bloqueado") -> 4 | O13: =COUNTIF(F15:F18,"Completado") -> 0 | P13: =IFERROR(O13/N13,0) -> 0 | Q13: Post-demo (spec) | R13: =COUNTIF(F15:F18,"En Progreso") -> 0 | S13: =COUNTIF(F15:F18,"Pendiente") -> 4
D14: ↳ Epic | E14: Subtarea | F14: Status | G14: Responsable | H14: Fecha Límite | I14: Comentarios
D15: E5-002 | E15: Configurar indexación de apelaciones resueltas | F15: Pendiente | I15: Post-demo
D16: E5-002 | E16: Definir criterios de similitud para recuperación | F16: Pendiente | I16: Post-demo
D17: E5-002 | E17: Configurar ranking por tasa de éxito | F17: Pendiente | I17: Post-demo
D18: E5-002 | E18: Pruebas de relevancia de resultados | F18: Pendiente | I18: Post-demo
D19: E5-003 | E19: Gestión del flujo de aprobación interna | F19: La respuesta pasa por revisión y aprobación antes del envío, con firma electrónica. | G19: Automate + ECM | H19: CRÍTICA | I19: Pendiente | J19: Fase 2 | N19: =COUNTIF(F21:F24,"Pendiente")+COUNTIF(F21:F24,"En Progreso")+COUNTIF(F21:F24,"En Revisión")+COUNTIF(F21:F24,"Completado")+COUNTIF(F21:F24,"Bloqueado") -> 4 | O19: =COUNTIF(F21:F24,"Completado") -> 0 | P19: =IFERROR(O19/N19,0) -> 0 | Q19: Post-demo (spec) | R19: =COUNTIF(F21:F24,"En Progreso") -> 0 | S19: =COUNTIF(F21:F24,"Pendiente") -> 4
D20: ↳ Epic | E20: Subtarea | F20: Status | G20: Responsable | H20: Fecha Límite | I20: Comentarios
D21: E5-003 | E21: Diseñar flujo de aprobación multinivel | F21: Pendiente | I21: Post-demo
D22: E5-003 | E22: Configurar workflow en Automate | F22: Pendiente | I22: Post-demo
D23: E5-003 | E23: Integrar firma electrónica si aplica | F23: Pendiente | I23: Post-demo
D24: E5-003 | E24: Pruebas de flujo completo de aprobación | F24: Pendiente | I24: Post-demo
D25: E5-004 | E25: Envío trazable de la apelación | F25: El envío queda registrado con fecha, hora y acuse de recibo en el expediente. | G25: Automate + ECM | H25: CRÍTICA | I25: Pendiente | J25: Fase 2 | N25: =COUNTIF(F27:F29,"Pendiente")+COUNTIF(F27:F29,"En Progreso")+COUNTIF(F27:F29,"En Revisión")+COUNTIF(F27:F29,"Completado")+COUNTIF(F27:F29,"Bloqueado") -> 3 | O25: =COUNTIF(F27:F29,"Completado") -> 0 | P25: =IFERROR(O25/N25,0) -> 0 | Q25: Post-demo (spec) | R25: =COUNTIF(F27:F29,"En Progreso") -> 0 | S25: =COUNTIF(F27:F29,"Pendiente") -> 3
D26: ↳ Epic | E26: Subtarea | F26: Status | G26: Responsable | H26: Fecha Límite | I26: Comentarios
D27: E5-004 | E27: Configurar envío automático con registro en ECM | F27: Pendiente | I27: Post-demo
D28: E5-004 | E28: Configurar captura del acuse de recibo | F28: Pendiente | I28: Post-demo
D29: E5-004 | E29: Validar inmutabilidad del registro de envío | F29: Pendiente | I29: Post-demo
D30: E5-005 | E30: Seguimiento del estado de la apelación | F30: Panel con estado de cada apelación: pendiente, aceptada, rechazada, en conciliación. | G30: Case Management | H30: CRÍTICA | I30: Pendiente | J30: Fase 2 | N30: =COUNTIF(F32:F35,"Pendiente")+COUNTIF(F32:F35,"En Progreso")+COUNTIF(F32:F35,"En Revisión")+COUNTIF(F32:F35,"Completado")+COUNTIF(F32:F35,"Bloqueado") -> 4 | O30: =COUNTIF(F32:F35,"Completado") -> 0 | P30: =IFERROR(O30/N30,0) -> 0 | Q30: Post-demo (spec) | R30: =COUNTIF(F32:F35,"En Progreso") -> 0 | S30: =COUNTIF(F32:F35,"Pendiente") -> 4
D31: ↳ Epic | E31: Subtarea | F31: Status | G31: Responsable | H31: Fecha Límite | I31: Comentarios
D32: E5-005 | E32: Configurar estados del caso de apelación | F32: Pendiente | I32: Post-demo
D33: E5-005 | E33: Configurar panel de seguimiento | F33: Pendiente | I33: Post-demo
D34: E5-005 | E34: Configurar alertas de cambio de estado | F34: Pendiente | I34: Post-demo
D35: E5-005 | E35: Capacitación al equipo auditor | F35: Pendiente | I35: Post-demo
D36: E5-006 | E36: Enriquecimiento de la base de conocimiento | F36: Cada glosa resuelta alimenta automáticamente el Knowledge Discovery. | G36: Knowledge Discovery | H36: MEDIA | I36: Pendiente | J36: Fase 3 | N36: =COUNTIF(F38:F40,"Pendiente")+COUNTIF(F38:F40,"En Progreso")+COUNTIF(F38:F40,"En Revisión")+COUNTIF(F38:F40,"Completado")+COUNTIF(F38:F40,"Bloqueado") -> 3 | O36: =COUNTIF(F38:F40,"Completado") -> 0 | P36: =IFERROR(O36/N36,0) -> 0 | Q36: Post-demo (spec) | R36: =COUNTIF(F38:F40,"En Progreso") -> 0 | S36: =COUNTIF(F38:F40,"Pendiente") -> 3
D37: ↳ Epic | E37: Subtarea | F37: Status | G37: Responsable | H37: Fecha Límite | I37: Comentarios
D38: E5-006 | E38: Configurar pipeline de retroalimentación al KD | F38: Pendiente | I38: Post-demo
D39: E5-006 | E39: Definir metadatos de resultado a capturar | F39: Pendiente | I39: Post-demo
D40: E5-006 | E40: Validar actualización de tasa de éxito | F40: Pendiente | I40: Post-demo
B42: Resumen de Etapa | N42: =COUNTIF(F7:F41,"Pendiente")+COUNTIF(F7:F41,"En Progreso")+COUNTIF(F7:F41,"En Revisión")+COUNTIF(F7:F41,"Completado")+COUNTIF(F7:F41,"Bloqueado") -> 22 | O42: =COUNTIF(F7:F41,"Completado") -> 0 | P42: =IFERROR(O42/N42,0) -> 0

Sheet E6 · Pago y Cierre
A2: HYLAND | Cuentas Médicas — Prestadores de Servicios
A3: Etapa 6 — Seguimiento de Pago, Conciliación y Cierre
A4: Post-demo (spec Etapa 10): conciliación de pagos, cierre del expediente y métricas de ciclo. No incluido en la demo actual.
B6: ☑ | D6: Epic ID | E6: Nombre del Epic | F6: Descripción | G6: Módulo Hyland | H6: Prioridad | I6: Status | J6: Fase | K6: Responsable | L6: Fecha Inicio | M6: Fecha Límite | N6: Subt. | O6: Compl. | P6: % Avance | Q6: Comentarios / Bloqueantes
D7: E6-001 | E7: Conciliación automática de pagos | F7: Cruza el valor pagado contra la cuenta original y los acuerdos de glosa (spec Etapa 10). | G7: Automate + ECM | H7: CRÍTICA | I7: Pendiente | J7: Fase 3 | N7: =COUNTIF(F9:F12,"Pendiente")+COUNTIF(F9:F12,"En Progreso")+COUNTIF(F9:F12,"En Revisión")+COUNTIF(F9:F12,"Completado")+COUNTIF(F9:F12,"Bloqueado") -> 4 | O7: =COUNTIF(F9:F12,"Completado") -> 0 | P7: =IFERROR(O7/N7,0) -> 0 | Q7: Post-demo (spec) | R7: =COUNTIF(F9:F12,"En Progreso") -> 0 | S7: =COUNTIF(F9:F12,"Pendiente") -> 4
D8: ↳ Epic | E8: Subtarea | F8: Status | G8: Responsable | H8: Fecha Límite | I8: Comentarios
D9: E6-001 | E9: Definir reglas de conciliación por tipo de acuerdo | F9: Pendiente | I9: Post-demo
D10: E6-001 | E10: Configurar proceso de conciliación en Automate | F10: Pendiente | I10: Post-demo
D11: E6-001 | E11: Configurar alerta por diferencias no esperadas | F11: Pendiente | I11: Post-demo
D12: E6-001 | E12: Pruebas con escenarios de pago parcial | F12: Pendiente | I12: Post-demo
D13: E6-002 | E13: Cierre del expediente con trazabilidad completa | F13: El expediente queda cerrado con el historial completo: facturación, glosas, apelaciones, pago. | G13: ECM | H13: CRÍTICA | I13: Pendiente | J13: Fase 3 | N13: =COUNTIF(F15:F18,"Pendiente")+COUNTIF(F15:F18,"En Progreso")+COUNTIF(F15:F18,"En Revisión")+COUNTIF(F15:F18,"Completado")+COUNTIF(F15:F18,"Bloqueado") -> 4 | O13: =COUNTIF(F15:F18,"Completado") -> 0 | P13: =IFERROR(O13/N13,0) -> 0 | Q13: Post-demo (spec) | R13: =COUNTIF(F15:F18,"En Progreso") -> 0 | S13: =COUNTIF(F15:F18,"Pendiente") -> 4
D14: ↳ Epic | E14: Subtarea | F14: Status | G14: Responsable | H14: Fecha Límite | I14: Comentarios
D15: E6-002 | E15: Definir checklist de cierre del expediente | F15: Pendiente | I15: Post-demo
D16: E6-002 | E16: Configurar sellado del expediente al cierre | F16: Pendiente | I16: Post-demo
D17: E6-002 | E17: Validar trazabilidad completa del timeline | F17: Pendiente | I17: Post-demo
D18: E6-002 | E18: Pruebas de acceso post-cierre (solo lectura) | F18: Pendiente | I18: Post-demo
D19: E6-003 | E19: Dashboard financiero de recupero | F19: Muestra por aseguradora: valor facturado, glosado, recuperado y perdido definitivamente. | G19: ECM / CIC | H19: CRÍTICA | I19: Pendiente | J19: Fase 3 | N19: =COUNTIF(F21:F24,"Pendiente")+COUNTIF(F21:F24,"En Progreso")+COUNTIF(F21:F24,"En Revisión")+COUNTIF(F21:F24,"Completado")+COUNTIF(F21:F24,"Bloqueado") -> 4 | O19: =COUNTIF(F21:F24,"Completado") -> 0 | P19: =IFERROR(O19/N19,0) -> 0 | Q19: Post-demo (spec) | R19: =COUNTIF(F21:F24,"En Progreso") -> 0 | S19: =COUNTIF(F21:F24,"Pendiente") -> 4
D20: ↳ Epic | E20: Subtarea | F20: Status | G20: Responsable | H20: Fecha Límite | I20: Comentarios
D21: E6-003 | E21: Definir métricas de recupero con el cliente | F21: Pendiente | I21: Post-demo
D22: E6-003 | E22: Configurar dashboard financiero en ECM/CIC | F22: Pendiente | I22: Post-demo
D23: E6-003 | E23: Configurar exportación a Excel/PDF | F23: Pendiente | I23: Post-demo
D24: E6-003 | E24: Capacitación a dirección financiera | F24: Pendiente | I24: Post-demo
D25: E6-004 | E25: Integración con ERP y cuentas por cobrar | F25: El cierre del expediente actualiza automáticamente el sistema contable del prestador. | G25: Automate + Integraciones | H25: CRÍTICA | I25: Pendiente | J25: Fase 3 | N25: =COUNTIF(F27:F30,"Pendiente")+COUNTIF(F27:F30,"En Progreso")+COUNTIF(F27:F30,"En Revisión")+COUNTIF(F27:F30,"Completado")+COUNTIF(F27:F30,"Bloqueado") -> 4 | O25: =COUNTIF(F27:F30,"Completado") -> 0 | P25: =IFERROR(O25/N25,0) -> 0 | Q25: Post-demo (spec) | R25: =COUNTIF(F27:F30,"En Progreso") -> 0 | S25: =COUNTIF(F27:F30,"Pendiente") -> 4
D26: ↳ Epic | E26: Subtarea | F26: Status | G26: Responsable | H26: Fecha Límite | I26: Comentarios
D27: E6-004 | E27: Mapear eventos de cierre a acciones en ERP | F27: Pendiente | I27: Post-demo
D28: E6-004 | E28: Desarrollar conector de integración ERP | F28: Pendiente | I28: Post-demo
D29: E6-004 | E29: Pruebas de consistencia contable end-to-end | F29: Pendiente | I29: Post-demo
D30: E6-004 | E30: Validación con auditoría financiera del cliente | F30: Pendiente | I30: Post-demo
D31: E6-005 | E31: Métricas de ciclo de cuentas médicas | F31: Tiempo promedio de pago, tasa de glosas, tasa de éxito en apelación, valor en riesgo. | G31: ECM / CIC | H31: CRÍTICA | I31: Pendiente | J31: Fase 3 | N31: =COUNTIF(F33:F36,"Pendiente")+COUNTIF(F33:F36,"En Progreso")+COUNTIF(F33:F36,"En Revisión")+COUNTIF(F33:F36,"Completado")+COUNTIF(F33:F36,"Bloqueado") -> 4 | O31: =COUNTIF(F33:F36,"Completado") -> 0 | P31: =IFERROR(O31/N31,0) -> 0 | Q31: Post-demo (spec) | R31: =COUNTIF(F33:F36,"En Progreso") -> 0 | S31: =COUNTIF(F33:F36,"Pendiente") -> 4
D32: ↳ Epic | E32: Subtarea | F32: Status | G32: Responsable | H32: Fecha Límite | I32: Comentarios
D33: E6-005 | E33: Definir KPIs del ciclo con el cliente | F33: Pendiente | I33: Post-demo
D34: E6-005 | E34: Configurar cálculo automático de métricas | F34: Pendiente | I34: Post-demo
D35: E6-005 | E35: Configurar reporte periódico automatizado | F35: Pendiente | I35: Post-demo
D36: E6-005 | E36: Validar con gerencia de facturación | F36: Pendiente | I36: Post-demo
D37: E6-006 | E37: Retención documental y cumplimiento normativo | F37: Gestión de retención según normativa vigente con pistas de auditoría inmutables. | G37: ECM | H37: MEDIA | I37: Pendiente | J37: Fase 3 | N37: =COUNTIF(F39:F42,"Pendiente")+COUNTIF(F39:F42,"En Progreso")+COUNTIF(F39:F42,"En Revisión")+COUNTIF(F39:F42,"Completado")+COUNTIF(F39:F42,"Bloqueado") -> 4 | O37: =COUNTIF(F39:F42,"Completado") -> 0 | P37: =IFERROR(O37/N37,0) -> 0 | Q37: Post-demo (spec) | R37: =COUNTIF(F39:F42,"En Progreso") -> 0 | S37: =COUNTIF(F39:F42,"Pendiente") -> 4
D38: ↳ Epic | E38: Subtarea | F38: Status | G38: Responsable | H38: Fecha Límite | I38: Comentarios
D39: E6-006 | E39: Mapear normativa de retención por país (CO/MX/PE) | F39: Pendiente | I39: Post-demo
D40: E6-006 | E40: Configurar políticas de retención en ECM | F40: Pendiente | I40: Post-demo
D41: E6-006 | E41: Configurar pistas de auditoría inmutables | F41: Pendiente | I41: Post-demo
D42: E6-006 | E42: Pruebas de cumplimiento normativo | F42: Pendiente | I42: Post-demo
...

Sheet 📋 Instrucciones
B2: HYLAND | Instrucciones del Epic Tracker
B4: Estructura del archivo
B5: 📊 Dashboard | C5: KPIs globales, tabla de progreso por etapa y resumen de alcance por Fase. Todo con fórmulas dinámicas.
B6: E1 – E6 | C6: Una hoja por etapa. Cada Epic (funcionalidad) tiene sus subtareas. E1–E2 concentran el alcance de la demo; E3–E6 son fases posteriores.
B7: Columna Fase (nuevo)
B8: Demo | C8: Funcionalidad incluida en la demostración final: implementada o en progreso.
B9: Fase 2 | C9: Alcance ampliado inmediato tras la demo (envío, RIPS, glosas base — spec Etapas 7-8).
B10: Fase 3 | C10: Roadmap posterior: apelación avanzada, pago, conciliación, cierre y modelos predictivos (spec Etapas 8-10).
B11: Estados
B12: Pendiente | C12: Identificado, no iniciado.
B13: En Progreso | C13: Activamente en desarrollo.
B14: En Revisión | C14: En validación con cliente o equipo técnico.
B15: Completado | C15: Finalizado y validado.
B16: Bloqueado | C16: Detenido por dependencia o problema técnico.
B17: Fórmulas dinámicas
B18: % Avance por Epic | C18: Completadas ÷ total de subtareas del Epic (cuenta solo estados válidos en la columna Status de subtareas).
B19: Dashboard | C19: Cuenta Epics por la columna Fase y subtareas por la columna Status. Se actualiza al cambiar estados o agregar subtareas dentro del rango del Epic.
B20: Editar | C20: Status y Fase son listas desplegables. Para agregar subtareas inserte filas dentro del rango del Epic.
B21: Nota de realineacion
B22: 2026-07-03 | C22: Tracker realineado con medical-records-demo-process-specification.md: se agregaron plugin/overview, intake, reejecucion IDP, reporting dashboard, los 3 agentes reales y la consola de Analisis; envio, glosas, apelacion y pago se marcaron como fases posteriores.
B24: Confidencial - Uso interno Hyland - 2026
